Workbook

Sheet 프로젝트일정 총괄표
A1: NO. | B1: 프로젝트명 | C1: 개발구분 | D1: 시작일 | E1: 종료일 | F1: 계획완료율 | G1: 진행율 | H1: 개발현황
A2: 1 | B2: 농약 살포기 BAP | C2: 제품규격 | D2: ='1.킨트_SS_BAP'!F10 -> 46033 | E2: ='1.킨트_SS_BAP'!G10 -> 46058 | F2: 1 | G2: ='1.킨트_SS_BAP'!I10 -> 0.5952381 | H2: =IF(G2>=F2,"정상",IF((F2-G2)>=0.5,"위험",IF((F2-G2)>=0.3,"주의","경고"))) -> 주의
C3: 제품개발 | D3: ='1.킨트_SS_BAP'!F17 -> 46031 | E3: ='1.킨트_SS_BAP'!G17 -> 46072 | F3: 1 | G3: ='1.킨트_SS_BAP'!I17 -> 0.27906977 | H3: =IF(G3>=F3,"정상",IF((F3-G3)>=0.5,"위험",IF((F3-G3)>=0.3,"주의","경고"))) -> 위험
A4: 2 | B4: HMC수소용역개발 P40, P56제품개발 | C4: 제품규격 | D4: ='2.10kWFC_배터리팩'!F10 -> 46015 | E4: ='2.10kWFC_배터리팩'!G10 -> 46083 | F4: 1 | G4: ='2.10kWFC_배터리팩'!I10 -> 0.90909091 | H4: =IF(G4>=F4,"정상",IF((F4-G4)>=0.5,"위험",IF((F4-G4)>=0.3,"주의","경고"))) -> 경고
C5: 제품개발 | D5: ='2.10kWFC_배터리팩'!F17 -> 46015 | E5: ='2.10kWFC_배터리팩'!G17 -> 46038 | F5: 1 | G5: ='2.10kWFC_배터리팩'!I17 -> 0.76086957 | H5: =IF(G5>=F5,"정상",IF((F5-G5)>=0.5,"위험",IF((F5-G5)>=0.3,"주의","경고"))) -> 경고
C6: 시제품제작 | D6: ='2.10kWFC_배터리팩'!F24 -> 46038 | E6: ='2.10kWFC_배터리팩'!G24 -> 46394 | F6: 1 | G6: ='2.10kWFC_배터리팩'!I24 -> 0.72184211 | H6: =IF(G6>=F6,"정상",IF((F6-G6)>=0.5,"위험",IF((F6-G6)>=0.3,"주의","경고"))) -> 경고
A7: 3 | B7: 항만용 AGV충전기 | C7: 제품규격 | D7: ='3.항만용AGV충전기'!F10 -> 46023 | E7: ='3.항만용AGV충전기'!G10 -> 46045 | F7: 1 | G7: ='3.항만용AGV충전기'!I10 -> 0.42121212 | H7: =IF(G7>=F7,"정상",IF((F7-G7)>=0.5,"위험",IF((F7-G7)>=0.3,"주의","경고"))) -> 위험
C8: 제품개발 | F8: 1 | G8: ='3.항만용AGV충전기'!I18
C9: 시제품제작 | F9: 1 | H9: =IF(G9>=F9,"정상",IF((F9-G9)>=0.5,"위험",IF((F9-G9)>=0.3,"주의","경고"))) -> 위험
A10: 4 | B10: RT트레인 개발 | C10: 제품규격 | F10: 1 | H10: =IF(G10>=F10,"정상",IF((F10-G10)>=0.5,"위험",IF((F10-G10)>=0.3,"주의","경고"))) -> 위험
C11: 제품개발 | F11: 1 | H11: =IF(G11>=F11,"정상",IF((F11-G11)>=0.5,"위험",IF((F11-G11)>=0.3,"주의","경고"))) -> 위험
C12: 시제품제작 | F12: 1 | H12: =IF(G12>=F12,"정상",IF((F12-G12)>=0.5,"위험",IF((F12-G12)>=0.3,"주의","경고"))) -> 위험
A13: 5 | B13: 친환경선박인증 | C13: 제품규격 | F13: 1 | H13: =IF(G13>=F13,"정상",IF((F13-G13)>=0.5,"위험",IF((F13-G13)>=0.3,"주의","경고"))) -> 위험
C14: 제품개발 | F14: 1 | H14: =IF(G14>=F14,"정상",IF((F14-G14)>=0.5,"위험",IF((F14-G14)>=0.3,"주의","경고"))) -> 위험
C15: 시제품제작 | F15: 1 | H15: =IF(G15>=F15,"정상",IF((F15-G15)>=0.5,"위험",IF((F15-G15)>=0.3,"주의","경고"))) -> 위험

Sheet 1.킨트_SS_BAP
B1: 프로젝트 일정 - 농약 살포기 BAP
C4: 현재일자 | D4: =TODAY() -> 46065 | F4: 프로젝트 담당자 | G4: 김미성 | I4: 일정표 간격(day) | T4: 완료일수 | X4: 잔여일수 | AB4: 총 진행률 % | AF4: 총 잔여기간 | AJ4: 초과일수
C6: 시작요일 | D6: 월요일 | F6: 시작일 | G6: 46033 | I6: 1 | J6: 0
S7: =TEXT(DATE(YEAR(S9),MONTH(S9),DAY(S9)),"M월") -> 1월 | T7: =IF(MONTH(T9)<>MONTH(S9),TEXT(DATE(YEAR(T9),MONTH(T9),DAY(T9)),"M월"),"") | U7: =IF(MONTH(U9)<>MONTH(T9),TEXT(DATE(YEAR(U9),MONTH(U9),DAY(U9)),"M월"),"") | V7: =IF(MONTH(V9)<>MONTH(U9),TEXT(DATE(YEAR(V9),MONTH(V9),DAY(V9)),"M월"),"") | W7: =IF(MONTH(W9)<>MONTH(V9),TEXT(DATE(YEAR(W9),MONTH(W9),DAY(W9)),"M월"),"") | X7: =IF(MONTH(X9)<>MONTH(W9),TEXT(DATE(YEAR(X9),MONTH(X9),DAY(X9)),"M월"),"") | Y7: =IF(MONTH(Y9)<>MONTH(X9),TEXT(DATE(YEAR(Y9),MONTH(Y9),DAY(Y9)),"M월"),"") | Z7: =IF(MONTH(Z9)<>MONTH(Y9),TEXT(DATE(YEAR(Z9),MONTH(Z9),DAY(Z9)),"M월"),"") | AA7: =IF(MONTH(AA9)<>MONTH(Z9),TEXT(DATE(YEAR(AA9),MONTH(AA9),DAY(AA9)),"M월"),"") | ... EH7: =IF(MONTH(EH9)<>MONTH(EG9),TEXT(DATE(YEAR(EH9),MONTH(EH9),DAY(EH9)),"M월"),"")
S8: =S9 -> 46034 | T8: =S8+$I$6 -> 46035 | U8: =T8+$I$6 -> 46036 | V8: =U8+$I$6 -> 46037 | W8: =V8+$I$6 -> 46038 | X8: =W8+$I$6 -> 46039 | Y8: =X8+$I$6 -> 46040 | Z8: =Y8+$I$6 -> 46041 | AA8: =Z8+$I$6 -> 46042 | ... EH8: =EG8+$I$6 -> 46153
B9: No | C9: 프로젝트명 | E9: 담당자 | F9: 시작일 | G9: 종료일(계획) | H9: 기간(계획) | I9: 진행률 % | J9: 종료일(지연) | K9: 기간(지연) | L9: 지연일수 | M9: 작업일수(계획) | N9: 작업일수(지연) | O9: 완료일수(계획) | P9: 완료일수(지연) | Q9: 잔여일수 | R9: Act. Remaining | S9: =$G$6-WEEKDAY($G$6,1)+INDEX({1;2;3;4;5;6;7},MATCH($D$6,{"일요일";"월요일";"화요일";"수요일";"목요일";"금요일";"토요일"},0)) -> 46034 | T9: =S9+$I$6 -> 46035 | U9: =T9+$I$6 -> 46036 | V9: =U9+$I$6 -> 46037 | W9: =V9+$I$6 -> 46038 | X9: =W9+$I$6 -> 46039 | Y9: =X9+$I$6 -> 46040 | Z9: =Y9+$I$6 -> 46041 | AA9: =Z9+$I$6 -> 46042 | ... EH9: =EG9+$I$6 -> 46153
B10: 1 | C10: 제품규격 | E10: 이우원 | F10: =MIN(F11:F16) -> 46033 | G10: =MAX(G11:G16) -> 46058 | H10: =IF(F10=0,"",G10-F10+1) -> 26 | I10: =IFERROR(SUMPRODUCT(H11:H16,I11:I16)/SUM(H11:H16),"") -> 0.5952381 | J10: =IF(MAX(J11:J16)="","",MAX(J11:J16)) -> 46058 | K10: =J10-F10+1 -> 26 | M10: =NETWORKDAYS(F10,G10) -> 19 | N10: =NETWORKDAYS(F10,J10) -> 19 | O10: =IFERROR(ROUNDDOWN(I10*H10,0),"") -> 15 | P10: =IFERROR(ROUNDDOWN(I10*K10,0),"") -> 15 | Q10: =IFERROR(H10-O10,"") -> 11 | R10: =K10-P10 -> 11
B11: 1.1 | C11: 제품사양 | E11: 이우원 | F11: 46033 | G11: 46037 | H11: =IF(F11="","",G11-F11+1) -> 5 | I11: 1 | J11: =G11 -> 46037 | K11: =IF(F11="","",J11-F11+1) -> 5 | L11: =IF(J11>G11,J11-G11,"") | M11: =NETWORKDAYS(F11,G11) -> 4 | N11: =NETWORKDAYS(F11,J11) -> 4 | O11: =IFERROR(ROUNDDOWN(I11*H11,0),"") -> 5 | P11: =IFERROR(ROUNDDOWN(I11*K11,0),"") -> 5 | Q11: =IFERROR(K11-P11,"") -> 0
B12: 1.2 | C12: 통신규약&DB작성 | E12: 이우원 | F12: 46035 | G12: 46037 | H12: =IF(F12="","",G12-F12+1) -> 3 | I12: 1 | J12: =G12 -> 46037 | K12: =IF(F12="","",J12-F12+1) -> 3 | L12: =IF(J12>G12,J12-G12,"") | M12: =NETWORKDAYS(F12,G12) -> 3 | N12: =NETWORKDAYS(F12,J12) -> 3 | O12: =IFERROR(ROUNDDOWN(I12*H12,0),"") -> 3 | P12: =IFERROR(ROUNDDOWN(I12*K12,0),"") -> 3 | Q12: =IFERROR(K12-P12,"") -> 0
B13: 1.3 | C13: 제품 구성도 | E13: 이우원 | F13: 46035 | G13: 46037 | H13: =IF(F13="","",G13-F13+1) -> 3 | I13: 0.5 | J13: =G13 -> 46037 | K13: =IF(F13="","",J13-F13+1) -> 3 | L13: =IF(J13>G13,J13-G13,"") | M13: =NETWORKDAYS(F13,G13) -> 3 | N13: =NETWORKDAYS(F13,J13) -> 3 | O13: =IFERROR(ROUNDDOWN(I13*H13,0),"") -> 1 | P13: =IFERROR(ROUNDDOWN(I13*K13,0),"") -> 1 | Q13: =IFERROR(K13-P13,"") -> 2
B14: 1.4 | C14: 보호 설정 기준 | E14: 이우원 | F14: 46035 | G14: 46037 | H14: =IF(F14="","",G14-F14+1) -> 3 | I14: 1 | J14: =G14 -> 46037 | K14: =IF(F14="","",J14-F14+1) -> 3 | L14: =IF(J14>G14,J14-G14,"") | M14: =NETWORKDAYS(F14,G14) -> 3 | N14: =NETWORKDAYS(F14,J14) -> 3 | O14: =IFERROR(ROUNDDOWN(I14*H14,0),"") -> 3 | P14: =IFERROR(ROUNDDOWN(I14*K14,0),"") -> 3 | Q14: =IFERROR(K14-P14,"") -> 0
B15: 1.5 | C15: 자체 검사 성적서 | E15: 박성호,이우원 | F15: 46052 | G15: 46058 | H15: =IF(F15="","",G15-F15+1) -> 7 | I15: 0 | J15: =G15 -> 46058 | K15: =IF(F15="","",J15-F15+1) -> 7 | L15: =IF(J15>G15,J15-G15,"") | M15: =NETWORKDAYS(F15,G15) -> 5 | N15: =NETWORKDAYS(F15,J15) -> 5 | O15: =IFERROR(ROUNDDOWN(I15*H15,0),"") -> 0 | P15: =IFERROR(ROUNDDOWN(I15*K15,0),"") -> 0 | Q15: =IFERROR(K15-P15,"") -> 7
B16: 1.6 | C16: 제작 계약 | E16: 김미성,이휘 | H16: =IF(F16="","",G16-F16+1) | I16: 0 | J16: =G16 -> 0 | K16: =IF(F16="","",J16-F16+1) | L16: =IF(J16>G16,J16-G16,"") | M16: =NETWORKDAYS(F16,G16) -> 0 | N16: =NETWORKDAYS(F16,J16) -> 0 | O16: =IFERROR(ROUNDDOWN(I16*H16,0),"") | P16: =IFERROR(ROUNDDOWN(I16*K16,0),"") | Q16: =IFERROR(K16-P16,"")
B17: 2 | C17: 제품개발 | E17: 문병길,김성열 | F17: =MIN(F18:F26) -> 46031 | G17: =MAX(G18:G26) -> 46072 | H17: =IF(F17=0,"",G17-F17+1) -> 42 | I17: =IFERROR(SUMPRODUCT(H18:H26,I18:I26)/SUM(H18:H26),"") -> 0.27906977 | J17: =IF(MAX(J18:J26)="","",MAX(J18:J26)) -> 46052 | K17: =J17-F17+1 -> 22 | M17: =NETWORKDAYS(F17,G17) -> 30 | N17: =NETWORKDAYS(F17,J17) -> 16 | O17: =IFERROR(ROUNDDOWN(I17*H17,0),"") -> 11 | P17: =IFERROR(ROUNDDOWN(I17*K17,0),"") -> 6 | Q17: =IFERROR(H17-O17,"") -> 31 | R17: =K17-P17 -> 16
B18: 2.1 | C18: 전장설계 및 BOM | E18: 김성열 | F18: 46035 | G18: 46037 | H18: =IF(F18="","",G18-F18+1) -> 3 | I18: 1 | J18: =G18 -> 46037 | K18: =IF(F18="","",J18-F18+1) -> 3 | L18: =IF(J18>G18,J18-G18,"") | M18: =NETWORKDAYS(F18,G18) -> 3 | N18: =NETWORKDAYS(F18,J18) -> 3 | O18: =IFERROR(ROUNDDOWN(I18*H18,0),"") -> 3 | P18: =IFERROR(ROUNDDOWN(I18*K18,0),"") -> 3 | Q18: =IFERROR(K18-P18,"") -> 0
B19: 2.2 | C19: 기구설계 3D 설계 | E19: 김성열 | F19: 46035 | G19: 46037 | H19: =IF(F19="","",G19-F19+1) -> 3 | I19: 1 | J19: =G19 -> 46037 | K19: =IF(F19="","",J19-F19+1) -> 3 | N19: =NETWORKDAYS(F19,J19) -> 3 | O19: =IFERROR(ROUNDDOWN(I19*H19,0),"") -> 3 | P19: =IFERROR(ROUNDDOWN(I19*K19,0),"") -> 3 | Q19: =IFERROR(K19-P19,"") -> 0
B20: 2.3 | C20: 제작설계 및 BOM | E20: 문병길 | F20: 46035 | G20: 46037 | H20: =IF(F20="","",G20-F20+1) -> 3 | I20: 1 | J20: =G20 -> 46037 | K20: =IF(F20="","",J20-F20+1) -> 3 | N20: =NETWORKDAYS(F20,J20) -> 3 | O20: =IFERROR(ROUNDDOWN(I20*H20,0),"") -> 3 | P20: =IFERROR(ROUNDDOWN(I20*K20,0),"") -> 3 | Q20: =IFERROR(K20-P20,"") -> 0
B21: 2.4 | C21: 배선제작도면 | E21: 문병길, 김성열 | F21: 46035 | G21: 46037 | H21: =IF(F21="","",G21-F21+1) -> 3 | I21: 1 | J21: =G21 -> 46037 | K21: =IF(F21="","",J21-F21+1) -> 3 | L21: =IF(J21>G21,J21-G21,"") | M21: =NETWORKDAYS(F21,G21) -> 3 | N21: =NETWORKDAYS(F21,J21) -> 3 | O21: =IFERROR(ROUNDDOWN(I21*H21,0),"") -> 3 | P21: =IFERROR(ROUNDDOWN(I21*K21,0),"") -> 3 | Q21: =IFERROR(K21-P21,"") -> 0
B22: 2.5 | C22: 제작 BOM 검토 | E22: 이우원 | F22: 46052 | G22: 46052 | H22: =IF(F22="","",G22-F22+1) -> 1 | J22: =G22 -> 46052 | K22: =IF(F22="","",J22-F22+1) -> 1 | N22: =NETWORKDAYS(F22,J22) -> 1
B23: 2.6 | C23: 소프트웨어 개발 | E23: 이우원,신입 | J23: =G23 -> 0 | K23: =IF(F23="","",J23-F23+1) | N23: =NETWORKDAYS(F23,J23) -> 0
B24: 3 | C24: 제품 출하(1차, 15EA) | F24: =MIN(F25:F33) -> 46031 | G24: =MAX(G25:G26) -> 46072
B25: 3.1 | C25: 시제품 제작 검증 | E25: 이우원,이휘 | F25: 46062 | G25: 46064
B26: 3.2 | C26: 제품 자체 및 공인 평가 | E26: 박성호,이우원 | F26: 46031 | G26: =WORKDAY(F26, H26-1) -> 46072 | H26: 30
B27: 3.3 | C27: 제품 선적 | E27: 이우원,이휘 | F27: 46086 | G27: =WORKDAY(F27, H27-1) -> 46092 | H27: 5

Sheet 2.10kWFC_배터리팩
B1: 프로젝트 일정 - 10KWFC_배터리팩
C4: 현재일자 | D4: =TODAY() -> 46065 | F4: 프로젝트 담당자 | G4: 문병길 | I4: 일정표 간격(day) | T4: 완료일수 | X4: 잔여일수 | AB4: 총 진행률 % | AF4: 총 잔여기간 | AJ4: 초과일수
C6: 시작요일 | D6: 월요일 | F6: 시작일 | G6: 45931 | I6: 1 | J6: 0
S7: =TEXT(DATE(YEAR(S9),MONTH(S9),DAY(S9)),"M월") -> 9월 | T7: =IF(MONTH(T9)<>MONTH(S9),TEXT(DATE(YEAR(T9),MONTH(T9),DAY(T9)),"M월"),"") | U7: =IF(MONTH(U9)<>MONTH(T9),TEXT(DATE(YEAR(U9),MONTH(U9),DAY(U9)),"M월"),"") -> 10월 | V7: =IF(MONTH(V9)<>MONTH(U9),TEXT(DATE(YEAR(V9),MONTH(V9),DAY(V9)),"M월"),"") | W7: =IF(MONTH(W9)<>MONTH(V9),TEXT(DATE(YEAR(W9),MONTH(W9),DAY(W9)),"M월"),"") | X7: =IF(MONTH(X9)<>MONTH(W9),TEXT(DATE(YEAR(X9),MONTH(X9),DAY(X9)),"M월"),"") | Y7: =IF(MONTH(Y9)<>MONTH(X9),TEXT(DATE(YEAR(Y9),MONTH(Y9),DAY(Y9)),"M월"),"") | Z7: =IF(MONTH(Z9)<>MONTH(Y9),TEXT(DATE(YEAR(Z9),MONTH(Z9),DAY(Z9)),"M월"),"") | AA7: =IF(MONTH(AA9)<>MONTH(Z9),TEXT(DATE(YEAR(AA9),MONTH(AA9),DAY(AA9)),"M월"),"") | ... EH7: =IF(MONTH(EH9)<>MONTH(EG9),TEXT(DATE(YEAR(EH9),MONTH(EH9),DAY(EH9)),"M월"),"")
S8: =S9 -> 45929 | T8: =S8+$I$6 -> 45930 | U8: =T8+$I$6 -> 45931 | V8: =U8+$I$6 -> 45932 | W8: =V8+$I$6 -> 45933 | X8: =W8+$I$6 -> 45934 | Y8: =X8+$I$6 -> 45935 | Z8: =Y8+$I$6 -> 45936 | AA8: =Z8+$I$6 -> 45937 | ... EH8: =EG8+$I$6 -> 46048
B9: No | C9: 프로젝트명 | E9: 담당자 | F9: 시작일 | G9: 종료일(계획) | H9: 기간(계획) | I9: 진행률 % | J9: 종료일(지연) | K9: 기간(지연) | L9: 지연일수 | M9: 작업일수(계획) | N9: 작업일수(지연) | O9: 완료일수(계획) | P9: 완료일수(지연) | Q9: 잔여일수 | R9: Act. Remaining | S9: =$G$6-WEEKDAY($G$6,1)+INDEX({1;2;3;4;5;6;7},MATCH($D$6,{"일요일";"월요일";"화요일";"수요일";"목요일";"금요일";"토요일"},0)) -> 45929 | T9: =S9+$I$6 -> 45930 | U9: =T9+$I$6 -> 45931 | V9: =U9+$I$6 -> 45932 | W9: =V9+$I$6 -> 45933 | X9: =W9+$I$6 -> 45934 | Y9: =X9+$I$6 -> 45935 | Z9: =Y9+$I$6 -> 45936 | AA9: =Z9+$I$6 -> 45937 | ... EH9: =EG9+$I$6 -> 46048
B10: 1 | C10: 제품규격 | D10: 이슈 번호 | E10: 이우원 | F10: =MIN(F11:F16) -> 46015 | G10: =MAX(G11:G16) -> 46083 | H10: =IF(F10=0,"",G10-F10+1) -> 69 | I10: =IFERROR(SUMPRODUCT(H11:H16,I11:I16)/SUM(H11:H16),"") -> 0.90909091 | J10: =IF(MAX(J11:J16)="","",MAX(J11:J16)) -> 46083 | K10: =J10-F10+1 -> 69 | M10: =NETWORKDAYS(F10,G10) -> 49 | N10: =NETWORKDAYS(F10,J10) -> 49 | O10: =IFERROR(ROUNDDOWN(I10*H10,0),"") -> 62 | P10: =IFERROR(ROUNDDOWN(I10*K10,0),"") -> 62 | Q10: =IFERROR(H10-O10,"") -> 7 | R10: =K10-P10 -> 7
B11: 1.1 | C11: 제품사양 | E11: 이우원 | F11: 46015 | G11: =WORKDAY(F11, H11-1) -> 46028 | H11: 10 | I11: 1 | J11: =G11 -> 46028 | K11: =IF(G11="","",J11-G11) -> 0 | L11: =IF(J11>G11,J11-G11,"") | M11: =NETWORKDAYS(F11,G11) -> 10 | O11: =IFERROR(ROUNDDOWN(I11*H11,0),"") -> 10 | P11: =IFERROR(ROUNDDOWN(I11*K11,0),"") -> 0
B12: 1.2 | C12: 통신규약 & DB작성 | E12: 이우원 | F12: 46015 | G12: =WORKDAY(F12, H12-1) -> 46028 | H12: 10 | I12: 1 | J12: =G12 -> 46028 | K12: =IF(G12="","",J12-G12) -> 0 | L12: =IF(J12>G12,J12-G12,"") | M12: =NETWORKDAYS(F12,G12) -> 10 | O12: =IFERROR(ROUNDDOWN(I12*H12,0),"") -> 10 | P12: =IFERROR(ROUNDDOWN(I12*K12,0),"") -> 0
B13: 1.3 | C13: 제품 구성도 | E13: 이우원 | F13: 46015 | G13: =WORKDAY(F13, H13-1) -> 46028 | H13: 10 | I13: 1 | J13: =G13 -> 46028 | K13: =IF(G13="","",J13-G13) -> 0 | L13: =IF(J13>G13,J13-G13,"") | M13: =NETWORKDAYS(F13,G13) -> 10 | O13: =IFERROR(ROUNDDOWN(I13*H13,0),"") -> 10 | P13: =IFERROR(ROUNDDOWN(I13*K13,0),"") -> 0
B14: 1.4 | C14: Part list | E14: 이우원 | F14: 46015 | G14: =WORKDAY(F14, H14-1) -> 46028 | H14: 10 | I14: 1 | J14: =G14 -> 46028 | K14: =IF(G14="","",J14-G14) -> 0 | L14: =IF(J14>G14,J14-G14,"") | M14: =NETWORKDAYS(F14,G14) -> 10 | O14: =IFERROR(ROUNDDOWN(I14*H14,0),"") -> 10 | P14: =IFERROR(ROUNDDOWN(I14*K14,0),"") -> 0
B15: 1.5 | C15: 보호설정기준 | E15: 이우원 | F15: 46015 | G15: =WORKDAY(F15, H15-1) -> 46028 | H15: 10 | I15: 1 | J15: =G15 -> 46028 | K15: =IF(G15="","",J15-G15) -> 0 | L15: =IF(J15>G15,J15-G15,"") | M15: =NETWORKDAYS(F15,G15) -> 10 | O15: =IFERROR(ROUNDDOWN(I15*H15,0),"") -> 10 | P15: =IFERROR(ROUNDDOWN(I15*K15,0),"") -> 0
B16: 1.6 | C16: 완료 보고서 | E16: 이우원 | F16: 46077 | G16: =WORKDAY(F16, H16-1) -> 46083 | H16: 5 | I16: 0 | J16: =G16 -> 46083 | K16: =IF(G16="","",J16-G16) -> 0 | L16: =IF(J16>G16,J16-G16,"") | M16: =NETWORKDAYS(F16,G16) -> 5 | O16: =IFERROR(ROUNDDOWN(I16*H16,0),"") -> 0 | P16: =IFERROR(ROUNDDOWN(I16*K16,0),"") -> 0
B17: 2 | C17: 제품개발 | E17: 김성열 | F17: =MIN(F18:F22) -> 46015 | G17: =MAX(G18:G22) -> 46038 | H17: =IF(F17=0,"",G17-F17+1) -> 24 | I17: =IFERROR(SUMPRODUCT(H18:H22,I18:I22)/SUM(H18:H22),"") -> 0.76086957 | J17: =IF(MAX(J18:J22)="","",MAX(J18:J22)) -> 46038 | K17: =J17-F17+1 -> 24 | M17: =NETWORKDAYS(F17,G17) -> 18 | N17: =NETWORKDAYS(F17,J17) -> 18 | O17: =IFERROR(ROUNDDOWN(I17*H17,0),"") -> 18 | P17: =IFERROR(ROUNDDOWN(I17*K17,0),"") -> 18 | Q17: =IFERROR(H17-O17,"") -> 6 | R17: =K17-P17 -> 6
B18: 2.1 | C18: 전기설계 및 BOM | E18: 김성열 | F18: 46015 | G18: =WORKDAY(F18, H18-1) -> 46028 | H18: 10 | I18: 0.5 | J18: =G18 -> 46028 | K18: =IF(F18="","",J18-F18+1) -> 14 | L18: =IF(J18>G18,J18-G18,"") | M18: =NETWORKDAYS(F18,G18) -> 10 | O18: =IFERROR(ROUNDDOWN(I18*H18,0),"") -> 5 | P18: =IFERROR(ROUNDDOWN(I18*K18,0),"") -> 7
B19: 2.3 | C19: 기구설계 및 BOM | E19: 문병길 | F19: 46015 | G19: 46038 | H19: =IF(F19="","",G19-F19+1) -> 24 | I19: 1 | J19: =G19 -> 46038 | K19: =IF(F19="","",J19-F19+1) -> 24 | L19: =IF(J19>G19,J19-G19,"") | M19: =NETWORKDAYS(F19,G19) -> 18 | O19: =IFERROR(ROUNDDOWN(I19*H19,0),"") -> 24 | P19: =IFERROR(ROUNDDOWN(I19*K19,0),"") -> 24
B20: 2.4 | C20: 배선제작지시서 | E20: 문병길, 김성열 | F20: 46015 | G20: =WORKDAY(F20, H20-1) -> 46028 | H20: 10 | I20: 0.5 | J20: =G20 -> 46028 | K20: =IF(F20="","",J20-F20+1) -> 14 | L20: =IF(J20>G20,J20-G20,"") | M20: =NETWORKDAYS(F20,G20) -> 10 | O20: =IFERROR(ROUNDDOWN(I20*H20,0),"") -> 5 | P20: =IFERROR(ROUNDDOWN(I20*K20,0),"") -> 7
B21: 2.5 | C21: 2D설계(제작도면) | E21: 문병길 | F21: 46015 | G21: 46038 | H21: =IF(F21="","",G21-F21+1) -> 24 | I21: 1 | J21: =G21 -> 46038 | K21: =IF(F21="","",J21-F21+1) -> 24 | L21: =IF(J21>G21,J21-G21,"") | M21: =NETWORKDAYS(F21,G21) -> 18 | O21: =IFERROR(ROUNDDOWN(I21*H21,0),"") -> 24 | P21: =IFERROR(ROUNDDOWN(I21*K21,0),"") -> 24
B22: 2.6 | C22: 제작BOM | E22: 김미성 | F22: 46015 | G22: 46038 | H22: =IF(F22="","",G22-F22+1) -> 24 | I22: 0.5 | J22: =G22 -> 46038 | K22: =IF(F22="","",J22-F22+1) -> 24 | L22: =IF(J22>G22,J22-G22,"") | M22: =NETWORKDAYS(F22,G22) -> 18 | O22: =IFERROR(ROUNDDOWN(I22*H22,0),"") -> 12 | P22: =IFERROR(ROUNDDOWN(I22*K22,0),"") -> 12
B23: 2.7 | C23: SW 개발 | E23: 신입, 김성열 | F23: 46024 | G23: =WORKDAY(F23, H23-1) -> 46065 | H23: 30 | I23: 0.8 | J23: =G23 -> 46065 | K23: =IF(F23="","",J23-F23+1) -> 42 | L23: =IF(J23>G23,J23-G23,"") | M23: =NETWORKDAYS(F23,G23) -> 30 | O23: =IFERROR(ROUNDDOWN(I23*H23,0),"") -> 24 | P23: =IFERROR(ROUNDDOWN(I23*K23,0),"") -> 33
B24: 3 | C24: 시제품제작 | E24: 김미성 | F24: =MIN(F25:F29) -> 46038 | G24: =MAX(G25:G29) -> 46394 | H24: =IF(F24=0,"",G24-F24+1) -> 357 | I24: =IFERROR(SUMPRODUCT(H25:H31,I25:I31)/SUM(H25:H31),"") -> 0.72184211 | J24: =IF(MAX(J25:J31)="","",MAX(J25:J31)) -> 46394 | K24: =J24-F24+1 -> 357 | M24: =NETWORKDAYS(F24,G24) -> 255 | N24: =NETWORKDAYS(F24,J24) -> 255 | O24: =IFERROR(ROUNDDOWN(I24*H24,0),"") -> 257 | P24: =IFERROR(ROUNDDOWN(I24*K24,0),"") -> 257 | Q24: =IFERROR(H24-O24,"") -> 100 | R24: =K24-P24 -> 100
B25: 3.1 | C25: 발주 및 입고 | E25: 박성호 | F25: =G22 -> 46038 | G25: =WORKDAY(F25, H25-1) -> 46065 | H25: 20 | I25: 1 | J25: =G25 -> 46065 | K25: =IF(F25="","",J25-F25+1) -> 28 | L25: =IF(J25>G25,J25-G25,"") | M25: =NETWORKDAYS(F25,G25) -> 20
B26: 3.2 | C26: LPF 제품 조립(1EA/2EA) 및 출하 | E26: 박성호 | F26: 46383 | G26: =WORKDAY(F26, H26-1) -> 46394 | H26: 10 | I26: 0.5 | J26: =G26 -> 46394 | K26: =IF(F26="","",J26-F26+1) -> 12 | L26: =IF(J26>G26,J26-G26,"") | M26: =NETWORKDAYS(F26,G26) -> 9
B27: 3.3 | C27: NCM 제품 조립(1EA/2EA) 및 출하 | E27: 박성호 | F27: 46042 | G27: =WORKDAY(F27, H27-1) -> 46056 | H27: 11 | I27: 1
B28: 3.4 | C28: NCM 제품 조립(2EA/2EA)) 및 출하 | E28: 박성호 | F28: 46062 | G28: =WORKDAY(F28, H28-1) -> 46065 | H28: 4 | I28: 0
B29: 3.5 | C29: LPF 제품 조립(2EA/2EA)) 및 출하 | E29: 박성호 | F29: 46071 | G29: =WORKDAY(F29, H29-1) -> 46077 | H29: 5 | I29: 0 | J29: =G29 -> 46077 | K29: =IF(F29="","",J29-F29+1) -> 7 | L29: =IF(J29>G29,J29-G29,"") | M29: =NETWORKDAYS(F29,G29) -> 5 | N29: =NETWORKDAYS(F29,J29) -> 5 | O29: =IFERROR(ROUNDDOWN(I29*H29,0),"") -> 0 | P29: =IFERROR(ROUNDDOWN(I29*K29,0),"") -> 0 | Q29: =IFERROR(K29-P29,"") -> 7
B30: 4 | C30: 자체 성능 평가 | E30: 김미성 | F30: =MIN(F31:F36) -> 46063 | G30: =MAX(G31:G37) -> 46092 | H30: =IF(F30=0,"",G30-F30+1) -> 30 | I30: =IFERROR(SUMPRODUCT(H31:H38,I31:I38)/SUM(H31:H38),"") -> 0.53947368 | J30: =IF(MAX(J31:J38)="","",MAX(J31:J38)) -> 46092 | K30: =J30-F30+1 -> 30 | M30: =NETWORKDAYS(F30,G30) -> 22 | N30: =NETWORKDAYS(F30,J30) -> 22 | O30: =IFERROR(ROUNDDOWN(I30*H30,0),"") -> 16 | P30: =IFERROR(ROUNDDOWN(I30*K30,0),"") -> 16 | Q30: =IFERROR(H30-O30,"") -> 14
B31: 3.1 | C31: 셀 성증 평가 | E31: 박유미 | F31: =G28 -> 46065 | G31: =WORKDAY(F31, H31-1) -> 46092 | H31: 20 | I31: 1 | J31: =G31 -> 46092
B32: 3.2 | C32: LPF 성능평가 (연속, 순간) 충방전 | D32: 관련문헌 | E32: 이우원 | F32: 46063 | G32: =WORKDAY(F32, H32-1) -> 46063 | H32: 1 | I32: 0.5 | J32: =G32 -> 46063
B33: 3.3 | C33: NCM 성능평가(연속, 순간) 충방전 | D33: 관련문헌 | E33: 이우원 | F33: =G32+1 -> 46064 | G33: =WORKDAY(F33, H33-1) -> 46064 | H33: 1
B34: 3.4 | C34: BMS 기능평가 | D34: 관련문헌 | E34: 이우원 | F34: =G33+1 -> 46065 | G34: =WORKDAY(F34, H34-1) -> 46065 | H34: 1
B35: 3.5 | C35: 주변 환경평가 | D35: 관련문헌 | E35: 문병길 | F35: 46072 | G35: =WORKDAY(F35, H35-1) -> 46078 | H35: 5
B36: 3.6 | C36: 성능 평가 | D36: 관련문헌 | E36: 이우원,김미성 | F36: 46072 | G36: =WORKDAY(F36, H36-1) -> 46078 | H36: 5
B37: 3.6 | C37: 기능 평가 | D37: 관련문헌 | E37: 김성열 | F37: =G36+1 -> 46079 | G37: =WORKDAY(F37, H37-1) -> 46085 | H37: 5

Sheet 4.수소이동형발전기
B1: 프로젝트 일정 - RT 트레인
C4: 현재일자 | D4: =TODAY() -> 46065 | F4: 프로젝트 담당자 | G4: 김성열 | I4: 일정표 간격(day) | T4: 완료일수 | X4: 잔여일수 | AB4: 총 진행률 % | AF4: 총 잔여기간 | AJ4: 초과일수
C6: 시작요일 | D6: 월요일 | F6: 시작일 | G6: 46082 | I6: 1 | J6: 0
S7: =TEXT(DATE(YEAR(S9),MONTH(S9),DAY(S9)),"M월") -> 3월 | T7: =IF(MONTH(T9)<>MONTH(S9),TEXT(DATE(YEAR(T9),MONTH(T9),DAY(T9)),"M월"),"") | U7: =IF(MONTH(U9)<>MONTH(T9),TEXT(DATE(YEAR(U9),MONTH(U9),DAY(U9)),"M월"),"") | V7: =IF(MONTH(V9)<>MONTH(U9),TEXT(DATE(YEAR(V9),MONTH(V9),DAY(V9)),"M월"),"") | W7: =IF(MONTH(W9)<>MONTH(V9),TEXT(DATE(YEAR(W9),MONTH(W9),DAY(W9)),"M월"),"") | X7: =IF(MONTH(X9)<>MONTH(W9),TEXT(DATE(YEAR(X9),MONTH(X9),DAY(X9)),"M월"),"") | Y7: =IF(MONTH(Y9)<>MONTH(X9),TEXT(DATE(YEAR(Y9),MONTH(Y9),DAY(Y9)),"M월"),"") | Z7: =IF(MONTH(Z9)<>MONTH(Y9),TEXT(DATE(YEAR(Z9),MONTH(Z9),DAY(Z9)),"M월"),"") | AA7: =IF(MONTH(AA9)<>MONTH(Z9),TEXT(DATE(YEAR(AA9),MONTH(AA9),DAY(AA9)),"M월"),"") | ... EH7: =IF(MONTH(EH9)<>MONTH(EG9),TEXT(DATE(YEAR(EH9),MONTH(EH9),DAY(EH9)),"M월"),"")
S8: =S9 -> 46083 | T8: =S8+$I$6 -> 46084 | U8: =T8+$I$6 -> 46085 | V8: =U8+$I$6 -> 46086 | W8: =V8+$I$6 -> 46087 | X8: =W8+$I$6 -> 46088 | Y8: =X8+$I$6 -> 46089 | Z8: =Y8+$I$6 -> 46090 | AA8: =Z8+$I$6 -> 46091 | ... EH8: =EG8+$I$6 -> 46202
B9: No | C9: 프로젝트명 | E9: 담당자 | F9: 시작일 | G9: 종료일(계획) | H9: 기간(계획) | I9: 진행률 % | J9: 종료일(지연) | K9: 기간(지연) | L9: 지연일수 | M9: 작업일수(계획) | N9: 작업일수(지연) | O9: 완료일수(계획) | P9: 완료일수(지연) | Q9: 잔여일수 | R9: Act. Remaining | S9: =$G$6-WEEKDAY($G$6,1)+INDEX({1;2;3;4;5;6;7},MATCH($D$6,{"일요일";"월요일";"화요일";"수요일";"목요일";"금요일";"토요일"},0)) -> 46083 | T9: =S9+$I$6 -> 46084 | U9: =T9+$I$6 -> 46085 | V9: =U9+$I$6 -> 46086 | W9: =V9+$I$6 -> 46087 | X9: =W9+$I$6 -> 46088 | Y9: =X9+$I$6 -> 46089 | Z9: =Y9+$I$6 -> 46090 | AA9: =Z9+$I$6 -> 46091 | ... EH9: =EG9+$I$6 -> 46202
B10: 1 | C10: 제품규격 | E10: 이우원 | F10: =MIN(F11:F17) -> 0 | G10: =MAX(G11:G17) -> 0 | H10: =IF(F10=0,"",G10-F10+1) | I10: =IFERROR(SUMPRODUCT(H11:H17,I11:I17)/SUM(H11:H17),"") | J10: =IF(MAX(J11:J17)="","",MAX(J11:J17)) -> 0 | K10: =J10-F10+1 -> 1 | M10: =NETWORKDAYS(F10,G10) -> 0 | N10: =NETWORKDAYS(F10,J10) -> 0 | O10: =IFERROR(ROUNDDOWN(I10*H10,0),"") | P10: =IFERROR(ROUNDDOWN(I10*K10,0),"") | Q10: =IFERROR(H10-O10,"") | R10: =K10-P10 -> #VALUE!
B11: 1.1 | C11: 제품사양 | H11: =IF(F11="","",G11-F11+1) | I11: 0 | J11: =G11 -> 0 | K11: =IF(F11="","",J11-F11+1) | L11: =IF(J11>G11,J11-G11,"") | M11: =NETWORKDAYS(F11,G11) -> 0 | N11: =NETWORKDAYS(F11,J11) -> 0 | O11: =IFERROR(ROUNDDOWN(I11*H11,0),"") | P11: =IFERROR(ROUNDDOWN(I11*K11,0),"") | Q11: =IFERROR(K11-P11,"")
B12: 1.2 | C12: 통신규약&DB작성 | H12: =IF(F12="","",G12-F12+1) | I12: 0 | J12: =G12 -> 0 | K12: =IF(F12="","",J12-F12+1) | L12: =IF(J12>G12,J12-G12,"") | M12: =NETWORKDAYS(F12,G12) -> 0 | N12: =NETWORKDAYS(F12,J12) -> 0 | O12: =IFERROR(ROUNDDOWN(I12*H12,0),"") | P12: =IFERROR(ROUNDDOWN(I12*K12,0),"") | Q12: =IFERROR(K12-P12,"")
B13: 1.3 | C13: 제품 구성도 | H13: =IF(F13="","",G13-F13+1) | I13: 0 | J13: =G13 -> 0 | K13: =IF(F13="","",J13-F13+1) | L13: =IF(J13>G13,J13-G13,"") | M13: =NETWORKDAYS(F13,G13) -> 0 | N13: =NETWORKDAYS(F13,J13) -> 0 | O13: =IFERROR(ROUNDDOWN(I13*H13,0),"") | P13: =IFERROR(ROUNDDOWN(I13*K13,0),"") | Q13: =IFERROR(K13-P13,"")
B14: 1.4 | C14: Part list | H14: =IF(F14="","",G14-F14+1) | I14: 0 | J14: =G14 -> 0 | K14: =IF(F14="","",J14-F14+1) | L14: =IF(J14>G14,J14-G14,"") | M14: =NETWORKDAYS(F14,G14) -> 0 | N14: =NETWORKDAYS(F14,J14) -> 0 | O14: =IFERROR(ROUNDDOWN(I14*H14,0),"") | P14: =IFERROR(ROUNDDOWN(I14*K14,0),"") | Q14: =IFERROR(K14-P14,"")
B15: 1.5 | C15: 보호 설정기준 | H15: =IF(F15="","",G15-F15+1) | I15: 0 | J15: =G15 -> 0 | K15: =IF(F15="","",J15-F15+1) | L15: =IF(J15>G15,J15-G15,"") | M15: =NETWORKDAYS(F15,G15) -> 0 | N15: =NETWORKDAYS(F15,J15) -> 0 | O15: =IFERROR(ROUNDDOWN(I15*H15,0),"") | P15: =IFERROR(ROUNDDOWN(I15*K15,0),"") | Q15: =IFERROR(K15-P15,"")
B16: 1.6 | C16: 자체 검사 성적서 | H16: =IF(F16="","",G16-F16+1) | I16: 0 | J16: =G16 -> 0 | K16: =IF(F16="","",J16-F16+1) | L16: =IF(J16>G16,J16-G16,"") | M16: =NETWORKDAYS(F16,G16) -> 0 | N16: =NETWORKDAYS(F16,J16) -> 0 | O16: =IFERROR(ROUNDDOWN(I16*H16,0),"") | P16: =IFERROR(ROUNDDOWN(I16*K16,0),"") | Q16: =IFERROR(K16-P16,"")
B17: 1.7 | C17: 제작 메뉴얼 | H17: =IF(F17="","",G17-F17+1) | I17: 0 | J17: =G17 -> 0 | K17: =IF(F17="","",J17-F17+1) | L17: =IF(J17>G17,J17-G17,"") | M17: =NETWORKDAYS(F17,G17) -> 0 | N17: =NETWORKDAYS(F17,J17) -> 0 | O17: =IFERROR(ROUNDDOWN(I17*H17,0),"") | P17: =IFERROR(ROUNDDOWN(I17*K17,0),"") | Q17: =IFERROR(K17-P17,"")
B18: 2 | C18: 제품개발 | E18: 이우원 | F18: =MIN(F19:F25) -> 0 | G18: =MAX(G19:G25) -> 0 | H18: =IF(F18=0,"",G18-F18+1) | I18: =IFERROR(SUMPRODUCT(H19:H25,I19:I25)/SUM(H19:H25),"") | J18: =IF(MAX(J19:J25)="","",MAX(J19:J25)) -> 0 | K18: =J18-F18+1 -> 1 | M18: =NETWORKDAYS(F18,G18) -> 0 | N18: =NETWORKDAYS(F18,J18) -> 0 | O18: =IFERROR(ROUNDDOWN(I18*H18,0),"") | P18: =IFERROR(ROUNDDOWN(I18*K18,0),"") | Q18: =IFERROR(H18-O18,"") | R18: =K18-P18 -> #VALUE!
B19: 2.1 | C19: 전기설계 | H19: =IF(F19="","",G19-F19+1) | I19: 0 | J19: =G19 -> 0 | K19: =IF(F19="","",J19-F19+1) | L19: =IF(J19>G19,J19-G19,"") | M19: =NETWORKDAYS(F19,G19) -> 0 | N19: =NETWORKDAYS(F19,J19) -> 0 | O19: =IFERROR(ROUNDDOWN(I19*H19,0),"") | P19: =IFERROR(ROUNDDOWN(I19*K19,0),"") | Q19: =IFERROR(K19-P19,"")
B20: 2.2 | C20: 전기 BOM 및 배선제작 | H20: =IF(F20="","",G20-F20+1) | I20: 0 | J20: =G20 -> 0 | K20: =IF(F20="","",J20-F20+1) | N20: =NETWORKDAYS(F20,J20) -> 0 | O20: =IFERROR(ROUNDDOWN(I20*H20,0),"") | P20: =IFERROR(ROUNDDOWN(I20*K20,0),"") | Q20: =IFERROR(K20-P20,"")
B21: 2.3 | C21: 3D설계 | H21: =IF(F21="","",G21-F21+1) | I21: 0 | J21: =G21 -> 0 | K21: =IF(F21="","",J21-F21+1) | N21: =NETWORKDAYS(F21,J21) -> 0 | O21: =IFERROR(ROUNDDOWN(I21*H21,0),"") | P21: =IFERROR(ROUNDDOWN(I21*K21,0),"") | Q21: =IFERROR(K21-P21,"")
B22: 2.4 | C22: 기구BOM | H22: =IF(F22="","",G22-F22+1) | I22: 0 | J22: =G22 -> 0 | K22: =IF(F22="","",J22-F22+1) | L22: =IF(J22>G22,J22-G22,"") | M22: =NETWORKDAYS(F22,G22) -> 0 | N22: =NETWORKDAYS(F22,J22) -> 0 | O22: =IFERROR(ROUNDDOWN(I22*H22,0),"") | P22: =IFERROR(ROUNDDOWN(I22*K22,0),"") | Q22: =IFERROR(K22-P22,"")
B23: 2.5 | C23: 2D설계(제작도면) | H23: =IF(F23="","",G23-F23+1) | I23: 0 | J23: =G23 -> 0 | K23: =IF(F23="","",J23-F23+1) | L23: =IF(J23>G23,J23-G23,"") | M23: =NETWORKDAYS(F23,G23) -> 0 | N23: =NETWORKDAYS(F23,J23) -> 0 | O23: =IFERROR(ROUNDDOWN(I23*H23,0),"") | P23: =IFERROR(ROUNDDOWN(I23*K23,0),"") | Q23: =IFERROR(K23-P23,"")
B24: 2.6 | C24: 제작BOM | H24: =IF(F24="","",G24-F24+1) | I24: 0 | J24: =G24 -> 0 | K24: =IF(F24="","",J24-F24+1) | L24: =IF(J24>G24,J24-G24,"") | M24: =NETWORKDAYS(F24,G24) -> 0 | N24: =NETWORKDAYS(F24,J24) -> 0 | O24: =IFERROR(ROUNDDOWN(I24*H24,0),"") | P24: =IFERROR(ROUNDDOWN(I24*K24,0),"") | Q24: =IFERROR(K24-P24,"")
B25: 2.7 | C25: 배선제작 | H25: =IF(F25="","",G25-F25+1) | I25: 0 | J25: =G25 -> 0 | K25: =IF(F25="","",J25-F25+1) | L25: =IF(J25>G25,J25-G25,"") | M25: =NETWORKDAYS(F25,G25) -> 0 | N25: =NETWORKDAYS(F25,J25) -> 0 | O25: =IFERROR(ROUNDDOWN(I25*H25,0),"") | P25: =IFERROR(ROUNDDOWN(I25*K25,0),"") | Q25: =IFERROR(K25-P25,"")
B26: 3 | C26: 시제품제작 | E26: 이우원 | F26: =MIN(F27:F32) -> 0 | G26: =MAX(G27:G32) -> 0 | H26: =IF(F26=0,"",G26-F26+1) | I26: =IFERROR(SUMPRODUCT(H27:H32,I27:I32)/SUM(H27:H32),"") | J26: =IF(MAX(J27:J32)="","",MAX(J27:J32)) -> 0 | K26: =J26-F26+1 -> 1 | M26: =NETWORKDAYS(F26,G26) -> 0 | N26: =NETWORKDAYS(F26,J26) -> 0 | O26: =IFERROR(ROUNDDOWN(I26*H26,0),"") | P26: =IFERROR(ROUNDDOWN(I26*K26,0),"") | Q26: =IFERROR(H26-O26,"") | R26: =K26-P26 -> #VALUE!
B27: 3.1 | C27: Part list 자재 발주 | H27: =IF(F27="","",G27-F27+1) | I27: 0 | J27: =G27 -> 0 | K27: =IF(F27="","",J27-F27+1) | L27: =IF(J27>G27,J27-G27,"") | M27: =NETWORKDAYS(F27,G27) -> 0 | N27: =NETWORKDAYS(F27,J27) -> 0 | O27: =IFERROR(ROUNDDOWN(I27*H27,0),"") | P27: =IFERROR(ROUNDDOWN(I27*K27,0),"") | Q27: =IFERROR(K27-P27,"")
B28: 2.2 | C28: 전기 자재 발주 | H28: =IF(F28="","",G28-F28+1) | I28: 0 | J28: =G28 -> 0 | K28: =IF(F28="","",J28-F28+1) | L28: =IF(J28>G28,J28-G28,"") | M28: =NETWORKDAYS(F28,G28) -> 0 | N28: =NETWORKDAYS(F28,J28) -> 0 | O28: =IFERROR(ROUNDDOWN(I28*H28,0),"") | P28: =IFERROR(ROUNDDOWN(I28*K28,0),"") | Q28: =IFERROR(K28-P28,"")
B29: 2.3 | C29: 기구 자재 발주 | H29: =IF(F29="","",G29-F29+1) | I29: 0 | J29: =G29 -> 0 | K29: =IF(F29="","",J29-F29+1) | L29: =IF(J29>G29,J29-G29,"") | M29: =NETWORKDAYS(F29,G29) -> 0 | N29: =NETWORKDAYS(F29,J29) -> 0 | O29: =IFERROR(ROUNDDOWN(I29*H29,0),"") | P29: =IFERROR(ROUNDDOWN(I29*K29,0),"") | Q29: =IFERROR(K29-P29,"")
B30: 2.4 | C30: 배선 자재 발주 | H30: =IF(F30="","",G30-F30+1) | I30: 0 | J30: =G30 -> 0 | K30: =IF(F30="","",J30-F30+1) | L30: =IF(J30>G30,J30-G30,"") | M30: =NETWORKDAYS(F30,G30) -> 0 | N30: =NETWORKDAYS(F30,J30) -> 0 | O30: =IFERROR(ROUNDDOWN(I30*H30,0),"") | P30: =IFERROR(ROUNDDOWN(I30*K30,0),"") | Q30: =IFERROR(K30-P30,"")
B31: 2.5 | C31: 제품 조립 | H31: =IF(F31="","",G31-F31+1) | I31: 0 | J31: =G31 -> 0 | K31: =IF(F31="","",J31-F31+1) | L31: =IF(J31>G31,J31-G31,"") | M31: =NETWORKDAYS(F31,G31) -> 0 | N31: =NETWORKDAYS(F31,J31) -> 0 | O31: =IFERROR(ROUNDDOWN(I31*H31,0),"") | P31: =IFERROR(ROUNDDOWN(I31*K31,0),"") | Q31: =IFERROR(K31-P31,"")
B32: 2.6 | C32: 출하 평가 | H32: =IF(F32="","",G32-F32+1) | I32: 0 | J32: =G32 -> 0 | K32: =IF(F32="","",J32-F32+1) | L32: =IF(J32>G32,J32-G32,"") | M32: =NETWORKDAYS(F32,G32) -> 0 | N32: =NETWORKDAYS(F32,J32) -> 0 | O32: =IFERROR(ROUNDDOWN(I32*H32,0),"") | P32: =IFERROR(ROUNDDOWN(I32*K32,0),"") | Q32: =IFERROR(K32-P32,"")

Sheet 3.항만용AGV충전기
B1: 프로젝트 일정 - 항만용AGV충전기
C4: 현재일자 | D4: =TODAY() -> 46065 | F4: 프로젝트 담당자 | G4: 이우원 | I4: 일정표 간격(day) | T4: 완료일수 | X4: 잔여일수 | AB4: 총 진행률 % | AF4: 총 잔여기간 | AJ4: 초과일수
C6: 시작요일 | D6: 월요일 | F6: 시작일 | G6: 46023 | I6: 1 | J6: 0
S7: =TEXT(DATE(YEAR(S9),MONTH(S9),DAY(S9)),"M월") -> 12월 | T7: =IF(MONTH(T9)<>MONTH(S9),TEXT(DATE(YEAR(T9),MONTH(T9),DAY(T9)),"M월"),"") | U7: =IF(MONTH(U9)<>MONTH(T9),TEXT(DATE(YEAR(U9),MONTH(U9),DAY(U9)),"M월"),"") | V7: =IF(MONTH(V9)<>MONTH(U9),TEXT(DATE(YEAR(V9),MONTH(V9),DAY(V9)),"M월"),"") -> 1월 | W7: =IF(MONTH(W9)<>MONTH(V9),TEXT(DATE(YEAR(W9),MONTH(W9),DAY(W9)),"M월"),"") | X7: =IF(MONTH(X9)<>MONTH(W9),TEXT(DATE(YEAR(X9),MONTH(X9),DAY(X9)),"M월"),"") | Y7: =IF(MONTH(Y9)<>MONTH(X9),TEXT(DATE(YEAR(Y9),MONTH(Y9),DAY(Y9)),"M월"),"") | Z7: =IF(MONTH(Z9)<>MONTH(Y9),TEXT(DATE(YEAR(Z9),MONTH(Z9),DAY(Z9)),"M월"),"") | AA7: =IF(MONTH(AA9)<>MONTH(Z9),TEXT(DATE(YEAR(AA9),MONTH(AA9),DAY(AA9)),"M월"),"") | ... EH7: =IF(MONTH(EH9)<>MONTH(EG9),TEXT(DATE(YEAR(EH9),MONTH(EH9),DAY(EH9)),"M월"),"")
S8: =S9 -> 46020 | T8: =S8+$I$6 -> 46021 | U8: =T8+$I$6 -> 46022 | V8: =U8+$I$6 -> 46023 | W8: =V8+$I$6 -> 46024 | X8: =W8+$I$6 -> 46025 | Y8: =X8+$I$6 -> 46026 | Z8: =Y8+$I$6 -> 46027 | AA8: =Z8+$I$6 -> 46028 | ... EH8: =EG8+$I$6 -> 46139
B9: No | C9: 프로젝트명 | E9: 담당자 | F9: 시작일 | G9: 종료일(계획) | H9: 기간(계획) | I9: 진행률 % | J9: 종료일(지연) | K9: 기간(지연) | L9: 지연일수 | M9: 작업일수(계획) | N9: 작업일수(지연) | O9: 완료일수(계획) | P9: 완료일수(지연) | Q9: 잔여일수 | R9: Act. Remaining | S9: =$G$6-WEEKDAY($G$6,1)+INDEX({1;2;3;4;5;6;7},MATCH($D$6,{"일요일";"월요일";"화요일";"수요일";"목요일";"금요일";"토요일"},0)) -> 46020 | T9: =S9+$I$6 -> 46021 | U9: =T9+$I$6 -> 46022 | V9: =U9+$I$6 -> 46023 | W9: =V9+$I$6 -> 46024 | X9: =W9+$I$6 -> 46025 | Y9: =X9+$I$6 -> 46026 | Z9: =Y9+$I$6 -> 46027 | AA9: =Z9+$I$6 -> 46028 | ... EH9: =EG9+$I$6 -> 46139
B10: 1 | C10: 제품규격 | E10: 이우원 | F10: =MIN(F11:F17) -> 46023 | G10: =MAX(G11:G17) -> 46045 | H10: =IF(F10=0,"",G10-F10+1) -> 23 | I10: =IFERROR(SUMPRODUCT(H11:H17,I11:I17)/SUM(H11:H17),"") -> 0.42121212 | J10: =IF(MAX(J11:J17)="","",MAX(J11:J17)) -> 46045 | K10: =J10-F10+1 -> 23 | M10: =NETWORKDAYS(F10,G10) -> 17 | N10: =NETWORKDAYS(F10,J10) -> 17 | O10: =IFERROR(ROUNDDOWN(I10*H10,0),"") -> 9 | P10: =IFERROR(ROUNDDOWN(I10*K10,0),"") -> 9 | Q10: =IFERROR(H10-O10,"") -> 14 | R10: =K10-P10 -> 14
B11: 1.1 | C11: 제품사양 | E11: 이우원 | H11: =IF(F11="","",G11-F11+1) | I11: 0 | J11: =G11 -> 0 | K11: =IF(F11="","",J11-F11+1) | L11: =IF(J11>G11,J11-G11,"") | M11: =NETWORKDAYS(F11,G11) -> 0 | N11: =NETWORKDAYS(F11,J11) -> 0 | O11: =IFERROR(ROUNDDOWN(I11*H11,0),"") | P11: =IFERROR(ROUNDDOWN(I11*K11,0),"") | Q11: =IFERROR(K11-P11,"")
B12: 1.2 | C12: 통신규약&DB작성 | E12: 이우원 | F12: 46023 | G12: 46042 | H12: =IF(F12="","",G12-F12+1) -> 20 | I12: 0.5 | J12: =G12 -> 46042 | K12: =IF(F12="","",J12-F12+1) -> 20 | L12: =IF(J12>G12,J12-G12,"") | M12: =NETWORKDAYS(F12,G12) -> 14 | N12: =NETWORKDAYS(F12,J12) -> 14 | O12: =IFERROR(ROUNDDOWN(I12*H12,0),"") -> 10 | P12: =IFERROR(ROUNDDOWN(I12*K12,0),"") -> 10 | Q12: =IFERROR(K12-P12,"") -> 10
B13: 1.3 | C13: 제품 구성도 | E13: 이우원 | F13: 46033 | G13: 46045 | H13: =IF(F13="","",G13-F13+1) -> 13 | I13: 0.3 | J13: =G13 -> 46045 | K13: =IF(F13="","",J13-F13+1) -> 13 | L13: =IF(J13>G13,J13-G13,"") | M13: =NETWORKDAYS(F13,G13) -> 10 | N13: =NETWORKDAYS(F13,J13) -> 10 | O13: =IFERROR(ROUNDDOWN(I13*H13,0),"") -> 3 | P13: =IFERROR(ROUNDDOWN(I13*K13,0),"") -> 3 | Q13: =IFERROR(K13-P13,"") -> 10
B14: 1.4 | C14: Part list | E14: 이우원 | H14: =IF(F14="","",G14-F14+1) | I14: 0 | J14: =G14 -> 0 | K14: =IF(F14="","",J14-F14+1) | L14: =IF(J14>G14,J14-G14,"") | M14: =NETWORKDAYS(F14,G14) -> 0 | N14: =NETWORKDAYS(F14,J14) -> 0 | O14: =IFERROR(ROUNDDOWN(I14*H14,0),"") | P14: =IFERROR(ROUNDDOWN(I14*K14,0),"") | Q14: =IFERROR(K14-P14,"")
B15: 1.5 | C15: 보호 설정기준 | E15: 박유미 | H15: =IF(F15="","",G15-F15+1) | I15: 0 | J15: =G15 -> 0 | K15: =IF(F15="","",J15-F15+1) | L15: =IF(J15>G15,J15-G15,"") | M15: =NETWORKDAYS(F15,G15) -> 0 | N15: =NETWORKDAYS(F15,J15) -> 0 | O15: =IFERROR(ROUNDDOWN(I15*H15,0),"") | P15: =IFERROR(ROUNDDOWN(I15*K15,0),"") | Q15: =IFERROR(K15-P15,"")
B16: 1.6 | C16: 자체 검사 성적서 | E16: 박유미 | H16: =IF(F16="","",G16-F16+1) | I16: 0 | J16: =G16 -> 0 | K16: =IF(F16="","",J16-F16+1) | L16: =IF(J16>G16,J16-G16,"") | M16: =NETWORKDAYS(F16,G16) -> 0 | N16: =NETWORKDAYS(F16,J16) -> 0 | O16: =IFERROR(ROUNDDOWN(I16*H16,0),"") | P16: =IFERROR(ROUNDDOWN(I16*K16,0),"") | Q16: =IFERROR(K16-P16,"")
B17: 1.7 | C17: 제작 메뉴얼 | E17: 이우원 | H17: =IF(F17="","",G17-F17+1) | I17: 0 | J17: =G17 -> 0 | K17: =IF(F17="","",J17-F17+1) | L17: =IF(J17>G17,J17-G17,"") | M17: =NETWORKDAYS(F17,G17) -> 0 | N17: =NETWORKDAYS(F17,J17) -> 0 | O17: =IFERROR(ROUNDDOWN(I17*H17,0),"") | P17: =IFERROR(ROUNDDOWN(I17*K17,0),"") | Q17: =IFERROR(K17-P17,"")
B18: 2 | C18: 제품개발 | E18: 이우원 | F18: =MIN(F19:F25) -> 0 | G18: =MAX(G19:G25) -> 0 | H18: =IF(F18=0,"",G18-F18+1) | I18: =IFERROR(SUMPRODUCT(H19:H25,I19:I25)/SUM(H19:H25),"") | J18: =IF(MAX(J19:J25)="","",MAX(J19:J25)) -> 0 | K18: =J18-F18+1 -> 1 | M18: =NETWORKDAYS(F18,G18) -> 0 | N18: =NETWORKDAYS(F18,J18) -> 0 | O18: =IFERROR(ROUNDDOWN(I18*H18,0),"") | P18: =IFERROR(ROUNDDOWN(I18*K18,0),"") | Q18: =IFERROR(H18-O18,"") | R18: =K18-P18 -> #VALUE!
B19: 2.1 | C19: 전기설계 | H19: =IF(F19="","",G19-F19+1) | I19: 0 | J19: =G19 -> 0 | K19: =IF(F19="","",J19-F19+1) | L19: =IF(J19>G19,J19-G19,"") | M19: =NETWORKDAYS(F19,G19) -> 0 | N19: =NETWORKDAYS(F19,J19) -> 0 | O19: =IFERROR(ROUNDDOWN(I19*H19,0),"") | P19: =IFERROR(ROUNDDOWN(I19*K19,0),"") | Q19: =IFERROR(K19-P19,"")
B20: 2.2 | C20: 전기 BOM 및 배선제작 | H20: =IF(F20="","",G20-F20+1) | I20: 0 | J20: =G20 -> 0 | K20: =IF(F20="","",J20-F20+1) | N20: =NETWORKDAYS(F20,J20) -> 0 | O20: =IFERROR(ROUNDDOWN(I20*H20,0),"") | P20: =IFERROR(ROUNDDOWN(I20*K20,0),"") | Q20: =IFERROR(K20-P20,"")
B21: 2.3 | C21: 3D설계 | H21: =IF(F21="","",G21-F21+1) | I21: 0 | J21: =G21 -> 0 | K21: =IF(F21="","",J21-F21+1) | N21: =NETWORKDAYS(F21,J21) -> 0 | O21: =IFERROR(ROUNDDOWN(I21*H21,0),"") | P21: =IFERROR(ROUNDDOWN(I21*K21,0),"") | Q21: =IFERROR(K21-P21,"")
B22: 2.4 | C22: 기구BOM | H22: =IF(F22="","",G22-F22+1) | I22: 0 | J22: =G22 -> 0 | K22: =IF(F22="","",J22-F22+1) | L22: =IF(J22>G22,J22-G22,"") | M22: =NETWORKDAYS(F22,G22) -> 0 | N22: =NETWORKDAYS(F22,J22) -> 0 | O22: =IFERROR(ROUNDDOWN(I22*H22,0),"") | P22: =IFERROR(ROUNDDOWN(I22*K22,0),"") | Q22: =IFERROR(K22-P22,"")
B23: 2.5 | C23: 2D설계(제작도면) | H23: =IF(F23="","",G23-F23+1) | I23: 0 | J23: =G23 -> 0 | K23: =IF(F23="","",J23-F23+1) | L23: =IF(J23>G23,J23-G23,"") | M23: =NETWORKDAYS(F23,G23) -> 0 | N23: =NETWORKDAYS(F23,J23) -> 0 | O23: =IFERROR(ROUNDDOWN(I23*H23,0),"") | P23: =IFERROR(ROUNDDOWN(I23*K23,0),"") | Q23: =IFERROR(K23-P23,"")
B24: 2.6 | C24: 제작BOM | H24: =IF(F24="","",G24-F24+1) | I24: 0 | J24: =G24 -> 0 | K24: =IF(F24="","",J24-F24+1) | L24: =IF(J24>G24,J24-G24,"") | M24: =NETWORKDAYS(F24,G24) -> 0 | N24: =NETWORKDAYS(F24,J24) -> 0 | O24: =IFERROR(ROUNDDOWN(I24*H24,0),"") | P24: =IFERROR(ROUNDDOWN(I24*K24,0),"") | Q24: =IFERROR(K24-P24,"")
B25: 2.7 | C25: 배선제작 | H25: =IF(F25="","",G25-F25+1) | I25: 0 | J25: =G25 -> 0 | K25: =IF(F25="","",J25-F25+1) | L25: =IF(J25>G25,J25-G25,"") | M25: =NETWORKDAYS(F25,G25) -> 0 | N25: =NETWORKDAYS(F25,J25) -> 0 | O25: =IFERROR(ROUNDDOWN(I25*H25,0),"") | P25: =IFERROR(ROUNDDOWN(I25*K25,0),"") | Q25: =IFERROR(K25-P25,"")
B26: 3 | C26: 시제품제작 | E26: 이우원 | F26: =MIN(F27:F32) -> 0 | G26: =MAX(G27:G32) -> 0 | H26: =IF(F26=0,"",G26-F26+1) | I26: =IFERROR(SUMPRODUCT(H27:H32,I27:I32)/SUM(H27:H32),"") | J26: =IF(MAX(J27:J32)="","",MAX(J27:J32)) -> 0 | K26: =J26-F26+1 -> 1 | M26: =NETWORKDAYS(F26,G26) -> 0 | N26: =NETWORKDAYS(F26,J26) -> 0 | O26: =IFERROR(ROUNDDOWN(I26*H26,0),"") | P26: =IFERROR(ROUNDDOWN(I26*K26,0),"") | Q26: =IFERROR(H26-O26,"") | R26: =K26-P26 -> #VALUE!
B27: 3.1 | C27: Part list 자재 발주 | H27: =IF(F27="","",G27-F27+1) | I27: 0 | J27: =G27 -> 0 | K27: =IF(F27="","",J27-F27+1) | L27: =IF(J27>G27,J27-G27,"") | M27: =NETWORKDAYS(F27,G27) -> 0 | N27: =NETWORKDAYS(F27,J27) -> 0 | O27: =IFERROR(ROUNDDOWN(I27*H27,0),"") | P27: =IFERROR(ROUNDDOWN(I27*K27,0),"") | Q27: =IFERROR(K27-P27,"")
B28: 2.2 | C28: 전기 자재 발주 | H28: =IF(F28="","",G28-F28+1) | I28: 0 | J28: =G28 -> 0 | K28: =IF(F28="","",J28-F28+1) | L28: =IF(J28>G28,J28-G28,"") | M28: =NETWORKDAYS(F28,G28) -> 0 | N28: =NETWORKDAYS(F28,J28) -> 0 | O28: =IFERROR(ROUNDDOWN(I28*H28,0),"") | P28: =IFERROR(ROUNDDOWN(I28*K28,0),"") | Q28: =IFERROR(K28-P28,"")
B29: 2.3 | C29: 기구 자재 발주 | H29: =IF(F29="","",G29-F29+1) | I29: 0 | J29: =G29 -> 0 | K29: =IF(F29="","",J29-F29+1) | L29: =IF(J29>G29,J29-G29,"") | M29: =NETWORKDAYS(F29,G29) -> 0 | N29: =NETWORKDAYS(F29,J29) -> 0 | O29: =IFERROR(ROUNDDOWN(I29*H29,0),"") | P29: =IFERROR(ROUNDDOWN(I29*K29,0),"") | Q29: =IFERROR(K29-P29,"")
B30: 2.4 | C30: 배선 자재 발주 | H30: =IF(F30="","",G30-F30+1) | I30: 0 | J30: =G30 -> 0 | K30: =IF(F30="","",J30-F30+1) | L30: =IF(J30>G30,J30-G30,"") | M30: =NETWORKDAYS(F30,G30) -> 0 | N30: =NETWORKDAYS(F30,J30) -> 0 | O30: =IFERROR(ROUNDDOWN(I30*H30,0),"") | P30: =IFERROR(ROUNDDOWN(I30*K30,0),"") | Q30: =IFERROR(K30-P30,"")
B31: 2.5 | C31: 제품 조립 | H31: =IF(F31="","",G31-F31+1) | I31: 0 | J31: =G31 -> 0 | K31: =IF(F31="","",J31-F31+1) | L31: =IF(J31>G31,J31-G31,"") | M31: =NETWORKDAYS(F31,G31) -> 0 | N31: =NETWORKDAYS(F31,J31) -> 0 | O31: =IFERROR(ROUNDDOWN(I31*H31,0),"") | P31: =IFERROR(ROUNDDOWN(I31*K31,0),"") | Q31: =IFERROR(K31-P31,"")
B32: 2.6 | C32: 출하 평가 | H32: =IF(F32="","",G32-F32+1) | I32: 0 | J32: =G32 -> 0 | K32: =IF(F32="","",J32-F32+1) | L32: =IF(J32>G32,J32-G32,"") | M32: =NETWORKDAYS(F32,G32) -> 0 | N32: =NETWORKDAYS(F32,J32) -> 0 | O32: =IFERROR(ROUNDDOWN(I32*H32,0),"") | P32: =IFERROR(ROUNDDOWN(I32*K32,0),"") | Q32: =IFERROR(K32-P32,"")

Sheet 5.친환경선박인증
B1: 프로젝트 일정 - 친환경 선박인증
C4: 현재일자 | D4: =TODAY() -> 46065 | F4: 프로젝트 담당자 | G4: 이우원 | I4: 일정표 간격(day) | T4: 완료일수 | X4: 잔여일수 | AB4: 총 진행률 % | AF4: 총 잔여기간 | AJ4: 초과일수
C6: 시작요일 | D6: 월요일 | F6: 시작일 | G6: 46023 | I6: 1 | J6: 0
S7: =TEXT(DATE(YEAR(S9),MONTH(S9),DAY(S9)),"M월") -> 12월 | T7: =IF(MONTH(T9)<>MONTH(S9),TEXT(DATE(YEAR(T9),MONTH(T9),DAY(T9)),"M월"),"") | U7: =IF(MONTH(U9)<>MONTH(T9),TEXT(DATE(YEAR(U9),MONTH(U9),DAY(U9)),"M월"),"") | V7: =IF(MONTH(V9)<>MONTH(U9),TEXT(DATE(YEAR(V9),MONTH(V9),DAY(V9)),"M월"),"") -> 1월 | W7: =IF(MONTH(W9)<>MONTH(V9),TEXT(DATE(YEAR(W9),MONTH(W9),DAY(W9)),"M월"),"") | X7: =IF(MONTH(X9)<>MONTH(W9),TEXT(DATE(YEAR(X9),MONTH(X9),DAY(X9)),"M월"),"") | Y7: =IF(MONTH(Y9)<>MONTH(X9),TEXT(DATE(YEAR(Y9),MONTH(Y9),DAY(Y9)),"M월"),"") | Z7: =IF(MONTH(Z9)<>MONTH(Y9),TEXT(DATE(YEAR(Z9),MONTH(Z9),DAY(Z9)),"M월"),"") | AA7: =IF(MONTH(AA9)<>MONTH(Z9),TEXT(DATE(YEAR(AA9),MONTH(AA9),DAY(AA9)),"M월"),"") | ... EH7: =IF(MONTH(EH9)<>MONTH(EG9),TEXT(DATE(YEAR(EH9),MONTH(EH9),DAY(EH9)),"M월"),"")
S8: =S9 -> 46020 | T8: =S8+$I$6 -> 46021 | U8: =T8+$I$6 -> 46022 | V8: =U8+$I$6 -> 46023 | W8: =V8+$I$6 -> 46024 | X8: =W8+$I$6 -> 46025 | Y8: =X8+$I$6 -> 46026 | Z8: =Y8+$I$6 -> 46027 | AA8: =Z8+$I$6 -> 46028 | ... EH8: =EG8+$I$6 -> 46139
B9: No | C9: 프로젝트명 | E9: 담당자 | F9: 시작일 | G9: 종료일(계획) | H9: 기간(계획) | I9: 진행률 % | J9: 종료일(지연) | K9: 기간(지연) | L9: 지연일수 | M9: 작업일수(계획) | N9: 작업일수(지연) | O9: 완료일수(계획) | P9: 완료일수(지연) | Q9: 잔여일수 | R9: Act. Remaining | S9: =$G$6-WEEKDAY($G$6,1)+INDEX({1;2;3;4;5;6;7},MATCH($D$6,{"일요일";"월요일";"화요일";"수요일";"목요일";"금요일";"토요일"},0)) -> 46020 | T9: =S9+$I$6 -> 46021 | U9: =T9+$I$6 -> 46022 | V9: =U9+$I$6 -> 46023 | W9: =V9+$I$6 -> 46024 | X9: =W9+$I$6 -> 46025 | Y9: =X9+$I$6 -> 46026 | Z9: =Y9+$I$6 -> 46027 | AA9: =Z9+$I$6 -> 46028 | ... EH9: =EG9+$I$6 -> 46139
B10: 1 | C10: 제품규격 | E10: 이우원 | F10: =MIN(F11:F17) -> 0 | G10: =MAX(G11:G17) -> 0 | H10: =IF(F10=0,"",G10-F10+1) | I10: =IFERROR(SUMPRODUCT(H11:H17,I11:I17)/SUM(H11:H17),"") | J10: =IF(MAX(J11:J17)="","",MAX(J11:J17)) -> 0 | K10: =J10-F10+1 -> 1 | M10: =NETWORKDAYS(F10,G10) -> 0 | N10: =NETWORKDAYS(F10,J10) -> 0 | O10: =IFERROR(ROUNDDOWN(I10*H10,0),"") | P10: =IFERROR(ROUNDDOWN(I10*K10,0),"") | Q10: =IFERROR(H10-O10,"") | R10: =K10-P10 -> #VALUE!
B11: 1.1 | C11: 제품사양 | H11: =IF(F11="","",G11-F11+1) | I11: 0 | J11: =G11 -> 0 | K11: =IF(F11="","",J11-F11+1) | L11: =IF(J11>G11,J11-G11,"") | M11: =NETWORKDAYS(F11,G11) -> 0 | N11: =NETWORKDAYS(F11,J11) -> 0 | O11: =IFERROR(ROUNDDOWN(I11*H11,0),"") | P11: =IFERROR(ROUNDDOWN(I11*K11,0),"") | Q11: =IFERROR(K11-P11,"")
B12: 1.2 | C12: 통신규약&DB작성 | H12: =IF(F12="","",G12-F12+1) | I12: 0 | J12: =G12 -> 0 | K12: =IF(F12="","",J12-F12+1) | L12: =IF(J12>G12,J12-G12,"") | M12: =NETWORKDAYS(F12,G12) -> 0 | N12: =NETWORKDAYS(F12,J12) -> 0 | O12: =IFERROR(ROUNDDOWN(I12*H12,0),"") | P12: =IFERROR(ROUNDDOWN(I12*K12,0),"") | Q12: =IFERROR(K12-P12,"")
B13: 1.3 | C13: 제품 구성도 | H13: =IF(F13="","",G13-F13+1) | I13: 0 | J13: =G13 -> 0 | K13: =IF(F13="","",J13-F13+1) | L13: =IF(J13>G13,J13-G13,"") | M13: =NETWORKDAYS(F13,G13) -> 0 | N13: =NETWORKDAYS(F13,J13) -> 0 | O13: =IFERROR(ROUNDDOWN(I13*H13,0),"") | P13: =IFERROR(ROUNDDOWN(I13*K13,0),"") | Q13: =IFERROR(K13-P13,"")
B14: 1.4 | C14: Part list | H14: =IF(F14="","",G14-F14+1) | I14: 0 | J14: =G14 -> 0 | K14: =IF(F14="","",J14-F14+1) | L14: =IF(J14>G14,J14-G14,"") | M14: =NETWORKDAYS(F14,G14) -> 0 | N14: =NETWORKDAYS(F14,J14) -> 0 | O14: =IFERROR(ROUNDDOWN(I14*H14,0),"") | P14: =IFERROR(ROUNDDOWN(I14*K14,0),"") | Q14: =IFERROR(K14-P14,"")
B15: 1.5 | C15: 보호 설정기준 | H15: =IF(F15="","",G15-F15+1) | I15: 0 | J15: =G15 -> 0 | K15: =IF(F15="","",J15-F15+1) | L15: =IF(J15>G15,J15-G15,"") | M15: =NETWORKDAYS(F15,G15) -> 0 | N15: =NETWORKDAYS(F15,J15) -> 0 | O15: =IFERROR(ROUNDDOWN(I15*H15,0),"") | P15: =IFERROR(ROUNDDOWN(I15*K15,0),"") | Q15: =IFERROR(K15-P15,"")
B16: 1.6 | C16: 자체 검사 성적서 | H16: =IF(F16="","",G16-F16+1) | I16: 0 | J16: =G16 -> 0 | K16: =IF(F16="","",J16-F16+1) | L16: =IF(J16>G16,J16-G16,"") | M16: =NETWORKDAYS(F16,G16) -> 0 | N16: =NETWORKDAYS(F16,J16) -> 0 | O16: =IFERROR(ROUNDDOWN(I16*H16,0),"") | P16: =IFERROR(ROUNDDOWN(I16*K16,0),"") | Q16: =IFERROR(K16-P16,"")
B17: 1.7 | C17: 제작 메뉴얼 | H17: =IF(F17="","",G17-F17+1) | I17: 0 | J17: =G17 -> 0 | K17: =IF(F17="","",J17-F17+1) | L17: =IF(J17>G17,J17-G17,"") | M17: =NETWORKDAYS(F17,G17) -> 0 | N17: =NETWORKDAYS(F17,J17) -> 0 | O17: =IFERROR(ROUNDDOWN(I17*H17,0),"") | P17: =IFERROR(ROUNDDOWN(I17*K17,0),"") | Q17: =IFERROR(K17-P17,"")
B18: 2 | C18: 제품개발 | E18: 이우원 | F18: =MIN(F19:F25) -> 0 | G18: =MAX(G19:G25) -> 0 | H18: =IF(F18=0,"",G18-F18+1) | I18: =IFERROR(SUMPRODUCT(H19:H25,I19:I25)/SUM(H19:H25),"") | J18: =IF(MAX(J19:J25)="","",MAX(J19:J25)) -> 0 | K18: =J18-F18+1 -> 1 | M18: =NETWORKDAYS(F18,G18) -> 0 | N18: =NETWORKDAYS(F18,J18) -> 0 | O18: =IFERROR(ROUNDDOWN(I18*H18,0),"") | P18: =IFERROR(ROUNDDOWN(I18*K18,0),"") | Q18: =IFERROR(H18-O18,"") | R18: =K18-P18 -> #VALUE!
B19: 2.1 | C19: 전기설계 | H19: =IF(F19="","",G19-F19+1) | I19: 0 | J19: =G19 -> 0 | K19: =IF(F19="","",J19-F19+1) | L19: =IF(J19>G19,J19-G19,"") | M19: =NETWORKDAYS(F19,G19) -> 0 | N19: =NETWORKDAYS(F19,J19) -> 0 | O19: =IFERROR(ROUNDDOWN(I19*H19,0),"") | P19: =IFERROR(ROUNDDOWN(I19*K19,0),"") | Q19: =IFERROR(K19-P19,"")
B20: 2.2 | C20: 전기 BOM 및 배선제작 | H20: =IF(F20="","",G20-F20+1) | I20: 0 | J20: =G20 -> 0 | K20: =IF(F20="","",J20-F20+1) | N20: =NETWORKDAYS(F20,J20) -> 0 | O20: =IFERROR(ROUNDDOWN(I20*H20,0),"") | P20: =IFERROR(ROUNDDOWN(I20*K20,0),"") | Q20: =IFERROR(K20-P20,"")
B21: 2.3 | C21: 3D설계 | H21: =IF(F21="","",G21-F21+1) | I21: 0 | J21: =G21 -> 0 | K21: =IF(F21="","",J21-F21+1) | N21: =NETWORKDAYS(F21,J21) -> 0 | O21: =IFERROR(ROUNDDOWN(I21*H21,0),"") | P21: =IFERROR(ROUNDDOWN(I21*K21,0),"") | Q21: =IFERROR(K21-P21,"")
B22: 2.4 | C22: 기구BOM | H22: =IF(F22="","",G22-F22+1) | I22: 0 | J22: =G22 -> 0 | K22: =IF(F22="","",J22-F22+1) | L22: =IF(J22>G22,J22-G22,"") | M22: =NETWORKDAYS(F22,G22) -> 0 | N22: =NETWORKDAYS(F22,J22) -> 0 | O22: =IFERROR(ROUNDDOWN(I22*H22,0),"") | P22: =IFERROR(ROUNDDOWN(I22*K22,0),"") | Q22: =IFERROR(K22-P22,"")
B23: 2.5 | C23: 2D설계(제작도면) | H23: =IF(F23="","",G23-F23+1) | I23: 0 | J23: =G23 -> 0 | K23: =IF(F23="","",J23-F23+1) | L23: =IF(J23>G23,J23-G23,"") | M23: =NETWORKDAYS(F23,G23) -> 0 | N23: =NETWORKDAYS(F23,J23) -> 0 | O23: =IFERROR(ROUNDDOWN(I23*H23,0),"") | P23: =IFERROR(ROUNDDOWN(I23*K23,0),"") | Q23: =IFERROR(K23-P23,"")
B24: 2.6 | C24: 제작BOM | H24: =IF(F24="","",G24-F24+1) | I24: 0 | J24: =G24 -> 0 | K24: =IF(F24="","",J24-F24+1) | L24: =IF(J24>G24,J24-G24,"") | M24: =NETWORKDAYS(F24,G24) -> 0 | N24: =NETWORKDAYS(F24,J24) -> 0 | O24: =IFERROR(ROUNDDOWN(I24*H24,0),"") | P24: =IFERROR(ROUNDDOWN(I24*K24,0),"") | Q24: =IFERROR(K24-P24,"")
B25: 2.7 | C25: 배선제작 | H25: =IF(F25="","",G25-F25+1) | I25: 0 | J25: =G25 -> 0 | K25: =IF(F25="","",J25-F25+1) | L25: =IF(J25>G25,J25-G25,"") | M25: =NETWORKDAYS(F25,G25) -> 0 | N25: =NETWORKDAYS(F25,J25) -> 0 | O25: =IFERROR(ROUNDDOWN(I25*H25,0),"") | P25: =IFERROR(ROUNDDOWN(I25*K25,0),"") | Q25: =IFERROR(K25-P25,"")
B26: 3 | C26: 시제품제작 | E26: 이우원 | F26: =MIN(F27:F32) -> 0 | G26: =MAX(G27:G32) -> 0 | H26: =IF(F26=0,"",G26-F26+1) | I26: =IFERROR(SUMPRODUCT(H27:H32,I27:I32)/SUM(H27:H32),"") | J26: =IF(MAX(J27:J32)="","",MAX(J27:J32)) -> 0 | K26: =J26-F26+1 -> 1 | M26: =NETWORKDAYS(F26,G26) -> 0 | N26: =NETWORKDAYS(F26,J26) -> 0 | O26: =IFERROR(ROUNDDOWN(I26*H26,0),"") | P26: =IFERROR(ROUNDDOWN(I26*K26,0),"") | Q26: =IFERROR(H26-O26,"") | R26: =K26-P26 -> #VALUE!
B27: 3.1 | C27: Part list 자재 발주 | H27: =IF(F27="","",G27-F27+1) | I27: 0 | J27: =G27 -> 0 | K27: =IF(F27="","",J27-F27+1) | L27: =IF(J27>G27,J27-G27,"") | M27: =NETWORKDAYS(F27,G27) -> 0 | N27: =NETWORKDAYS(F27,J27) -> 0 | O27: =IFERROR(ROUNDDOWN(I27*H27,0),"") | P27: =IFERROR(ROUNDDOWN(I27*K27,0),"") | Q27: =IFERROR(K27-P27,"")
B28: 2.2 | C28: 전기 자재 발주 | H28: =IF(F28="","",G28-F28+1) | I28: 0 | J28: =G28 -> 0 | K28: =IF(F28="","",J28-F28+1) | L28: =IF(J28>G28,J28-G28,"") | M28: =NETWORKDAYS(F28,G28) -> 0 | N28: =NETWORKDAYS(F28,J28) -> 0 | O28: =IFERROR(ROUNDDOWN(I28*H28,0),"") | P28: =IFERROR(ROUNDDOWN(I28*K28,0),"") | Q28: =IFERROR(K28-P28,"")
B29: 2.3 | C29: 기구 자재 발주 | H29: =IF(F29="","",G29-F29+1) | I29: 0 | J29: =G29 -> 0 | K29: =IF(F29="","",J29-F29+1) | L29: =IF(J29>G29,J29-G29,"") | M29: =NETWORKDAYS(F29,G29) -> 0 | N29: =NETWORKDAYS(F29,J29) -> 0 | O29: =IFERROR(ROUNDDOWN(I29*H29,0),"") | P29: =IFERROR(ROUNDDOWN(I29*K29,0),"") | Q29: =IFERROR(K29-P29,"")
B30: 2.4 | C30: 배선 자재 발주 | H30: =IF(F30="","",G30-F30+1) | I30: 0 | J30: =G30 -> 0 | K30: =IF(F30="","",J30-F30+1) | L30: =IF(J30>G30,J30-G30,"") | M30: =NETWORKDAYS(F30,G30) -> 0 | N30: =NETWORKDAYS(F30,J30) -> 0 | O30: =IFERROR(ROUNDDOWN(I30*H30,0),"") | P30: =IFERROR(ROUNDDOWN(I30*K30,0),"") | Q30: =IFERROR(K30-P30,"")
B31: 2.5 | C31: 제품 조립 | H31: =IF(F31="","",G31-F31+1) | I31: 0 | J31: =G31 -> 0 | K31: =IF(F31="","",J31-F31+1) | L31: =IF(J31>G31,J31-G31,"") | M31: =NETWORKDAYS(F31,G31) -> 0 | N31: =NETWORKDAYS(F31,J31) -> 0 | O31: =IFERROR(ROUNDDOWN(I31*H31,0),"") | P31: =IFERROR(ROUNDDOWN(I31*K31,0),"") | Q31: =IFERROR(K31-P31,"")
B32: 2.6 | C32: 출하 평가 | H32: =IF(F32="","",G32-F32+1) | I32: 0 | J32: =G32 -> 0 | K32: =IF(F32="","",J32-F32+1) | L32: =IF(J32>G32,J32-G32,"") | M32: =NETWORKDAYS(F32,G32) -> 0 | N32: =NETWORKDAYS(F32,J32) -> 0 | O32: =IFERROR(ROUNDDOWN(I32*H32,0),"") | P32: =IFERROR(ROUNDDOWN(I32*K32,0),"") | Q32: =IFERROR(K32-P32,"")

Sheet 6.RT크레인
B1: 프로젝트 일정 - 친환경 선박인증
C4: 현재일자 | D4: =TODAY() -> 46065 | F4: 프로젝트 담당자 | G4: 이우원 | I4: 일정표 간격(day) | T4: 완료일수 | X4: 잔여일수 | AB4: 총 진행률 % | AF4: 총 잔여기간 | AJ4: 초과일수
C6: 시작요일 | D6: 월요일 | F6: 시작일 | G6: 46082 | I6: 1 | J6: 0
S7: =TEXT(DATE(YEAR(S9),MONTH(S9),DAY(S9)),"M월") -> 3월 | T7: =IF(MONTH(T9)<>MONTH(S9),TEXT(DATE(YEAR(T9),MONTH(T9),DAY(T9)),"M월"),"") | U7: =IF(MONTH(U9)<>MONTH(T9),TEXT(DATE(YEAR(U9),MONTH(U9),DAY(U9)),"M월"),"") | V7: =IF(MONTH(V9)<>MONTH(U9),TEXT(DATE(YEAR(V9),MONTH(V9),DAY(V9)),"M월"),"") | W7: =IF(MONTH(W9)<>MONTH(V9),TEXT(DATE(YEAR(W9),MONTH(W9),DAY(W9)),"M월"),"") | X7: =IF(MONTH(X9)<>MONTH(W9),TEXT(DATE(YEAR(X9),MONTH(X9),DAY(X9)),"M월"),"") | Y7: =IF(MONTH(Y9)<>MONTH(X9),TEXT(DATE(YEAR(Y9),MONTH(Y9),DAY(Y9)),"M월"),"") | Z7: =IF(MONTH(Z9)<>MONTH(Y9),TEXT(DATE(YEAR(Z9),MONTH(Z9),DAY(Z9)),"M월"),"") | AA7: =IF(MONTH(AA9)<>MONTH(Z9),TEXT(DATE(YEAR(AA9),MONTH(AA9),DAY(AA9)),"M월"),"") | ... EH7: =IF(MONTH(EH9)<>MONTH(EG9),TEXT(DATE(YEAR(EH9),MONTH(EH9),DAY(EH9)),"M월"),"")
S8: =S9 -> 46083 | T8: =S8+$I$6 -> 46084 | U8: =T8+$I$6 -> 46085 | V8: =U8+$I$6 -> 46086 | W8: =V8+$I$6 -> 46087 | X8: =W8+$I$6 -> 46088 | Y8: =X8+$I$6 -> 46089 | Z8: =Y8+$I$6 -> 46090 | AA8: =Z8+$I$6 -> 46091 | ... EH8: =EG8+$I$6 -> 46202
B9: No | C9: 프로젝트명 | E9: 담당자 | F9: 시작일 | G9: 종료일(계획) | H9: 기간(계획) | I9: 진행률 % | J9: 종료일(지연) | K9: 기간(지연) | L9: 지연일수 | M9: 작업일수(계획) | N9: 작업일수(지연) | O9: 완료일수(계획) | P9: 완료일수(지연) | Q9: 잔여일수 | R9: Act. Remaining | S9: =$G$6-WEEKDAY($G$6,1)+INDEX({1;2;3;4;5;6;7},MATCH($D$6,{"일요일";"월요일";"화요일";"수요일";"목요일";"금요일";"토요일"},0)) -> 46083 | T9: =S9+$I$6 -> 46084 | U9: =T9+$I$6 -> 46085 | V9: =U9+$I$6 -> 46086 | W9: =V9+$I$6 -> 46087 | X9: =W9+$I$6 -> 46088 | Y9: =X9+$I$6 -> 46089 | Z9: =Y9+$I$6 -> 46090 | AA9: =Z9+$I$6 -> 46091 | ... EH9: =EG9+$I$6 -> 46202
B10: 1 | C10: 제품규격 | E10: 이우원 | F10: =MIN(F11:F17) -> 0 | G10: =MAX(G11:G17) -> 0 | H10: =IF(F10=0,"",G10-F10+1) | I10: =IFERROR(SUMPRODUCT(H11:H17,I11:I17)/SUM(H11:H17),"") | J10: =IF(MAX(J11:J17)="","",MAX(J11:J17)) -> 0 | K10: =J10-F10+1 -> 1 | M10: =NETWORKDAYS(F10,G10) -> 0 | N10: =NETWORKDAYS(F10,J10) -> 0 | O10: =IFERROR(ROUNDDOWN(I10*H10,0),"") | P10: =IFERROR(ROUNDDOWN(I10*K10,0),"") | Q10: =IFERROR(H10-O10,"") | R10: =K10-P10 -> #VALUE!
B11: 1.1 | C11: 제품사양 | H11: =IF(F11="","",G11-F11+1) | I11: 0 | J11: =G11 -> 0 | K11: =IF(F11="","",J11-F11+1) | L11: =IF(J11>G11,J11-G11,"") | M11: =NETWORKDAYS(F11,G11) -> 0 | N11: =NETWORKDAYS(F11,J11) -> 0 | O11: =IFERROR(ROUNDDOWN(I11*H11,0),"") | P11: =IFERROR(ROUNDDOWN(I11*K11,0),"") | Q11: =IFERROR(K11-P11,"")
B12: 1.2 | C12: 통신규약&DB작성 | H12: =IF(F12="","",G12-F12+1) | I12: 0 | J12: =G12 -> 0 | K12: =IF(F12="","",J12-F12+1) | L12: =IF(J12>G12,J12-G12,"") | M12: =NETWORKDAYS(F12,G12) -> 0 | N12: =NETWORKDAYS(F12,J12) -> 0 | O12: =IFERROR(ROUNDDOWN(I12*H12,0),"") | P12: =IFERROR(ROUNDDOWN(I12*K12,0),"") | Q12: =IFERROR(K12-P12,"")
B13: 1.3 | C13: 제품 구성도 | H13: =IF(F13="","",G13-F13+1) | I13: 0 | J13: =G13 -> 0 | K13: =IF(F13="","",J13-F13+1) | L13: =IF(J13>G13,J13-G13,"") | M13: =NETWORKDAYS(F13,G13) -> 0 | N13: =NETWORKDAYS(F13,J13) -> 0 | O13: =IFERROR(ROUNDDOWN(I13*H13,0),"") | P13: =IFERROR(ROUNDDOWN(I13*K13,0),"") | Q13: =IFERROR(K13-P13,"")
B14: 1.4 | C14: Part list | H14: =IF(F14="","",G14-F14+1) | I14: 0 | J14: =G14 -> 0 | K14: =IF(F14="","",J14-F14+1) | L14: =IF(J14>G14,J14-G14,"") | M14: =NETWORKDAYS(F14,G14) -> 0 | N14: =NETWORKDAYS(F14,J14) -> 0 | O14: =IFERROR(ROUNDDOWN(I14*H14,0),"") | P14: =IFERROR(ROUNDDOWN(I14*K14,0),"") | Q14: =IFERROR(K14-P14,"")
B15: 1.5 | C15: 보호 설정기준 | H15: =IF(F15="","",G15-F15+1) | I15: 0 | J15: =G15 -> 0 | K15: =IF(F15="","",J15-F15+1) | L15: =IF(J15>G15,J15-G15,"") | M15: =NETWORKDAYS(F15,G15) -> 0 | N15: =NETWORKDAYS(F15,J15) -> 0 | O15: =IFERROR(ROUNDDOWN(I15*H15,0),"") | P15: =IFERROR(ROUNDDOWN(I15*K15,0),"") | Q15: =IFERROR(K15-P15,"")
B16: 1.6 | C16: 자체 검사 성적서 | H16: =IF(F16="","",G16-F16+1) | I16: 0 | J16: =G16 -> 0 | K16: =IF(F16="","",J16-F16+1) | L16: =IF(J16>G16,J16-G16,"") | M16: =NETWORKDAYS(F16,G16) -> 0 | N16: =NETWORKDAYS(F16,J16) -> 0 | O16: =IFERROR(ROUNDDOWN(I16*H16,0),"") | P16: =IFERROR(ROUNDDOWN(I16*K16,0),"") | Q16: =IFERROR(K16-P16,"")
B17: 1.7 | C17: 제작 메뉴얼 | H17: =IF(F17="","",G17-F17+1) | I17: 0 | J17: =G17 -> 0 | K17: =IF(F17="","",J17-F17+1) | L17: =IF(J17>G17,J17-G17,"") | M17: =NETWORKDAYS(F17,G17) -> 0 | N17: =NETWORKDAYS(F17,J17) -> 0 | O17: =IFERROR(ROUNDDOWN(I17*H17,0),"") | P17: =IFERROR(ROUNDDOWN(I17*K17,0),"") | Q17: =IFERROR(K17-P17,"")
B18: 2 | C18: 제품개발 | E18: 이우원 | F18: =MIN(F19:F25) -> 0 | G18: =MAX(G19:G25) -> 0 | H18: =IF(F18=0,"",G18-F18+1) | I18: =IFERROR(SUMPRODUCT(H19:H25,I19:I25)/SUM(H19:H25),"") | J18: =IF(MAX(J19:J25)="","",MAX(J19:J25)) -> 0 | K18: =J18-F18+1 -> 1 | M18: =NETWORKDAYS(F18,G18) -> 0 | N18: =NETWORKDAYS(F18,J18) -> 0 | O18: =IFERROR(ROUNDDOWN(I18*H18,0),"") | P18: =IFERROR(ROUNDDOWN(I18*K18,0),"") | Q18: =IFERROR(H18-O18,"") | R18: =K18-P18 -> #VALUE!
B19: 2.1 | C19: 전기설계 | H19: =IF(F19="","",G19-F19+1) | I19: 0 | J19: =G19 -> 0 | K19: =IF(F19="","",J19-F19+1) | L19: =IF(J19>G19,J19-G19,"") | M19: =NETWORKDAYS(F19,G19) -> 0 | N19: =NETWORKDAYS(F19,J19) -> 0 | O19: =IFERROR(ROUNDDOWN(I19*H19,0),"") | P19: =IFERROR(ROUNDDOWN(I19*K19,0),"") | Q19: =IFERROR(K19-P19,"")
B20: 2.2 | C20: 전기 BOM 및 배선제작 | H20: =IF(F20="","",G20-F20+1) | I20: 0 | J20: =G20 -> 0 | K20: =IF(F20="","",J20-F20+1) | N20: =NETWORKDAYS(F20,J20) -> 0 | O20: =IFERROR(ROUNDDOWN(I20*H20,0),"") | P20: =IFERROR(ROUNDDOWN(I20*K20,0),"") | Q20: =IFERROR(K20-P20,"")
B21: 2.3 | C21: 3D설계 | H21: =IF(F21="","",G21-F21+1) | I21: 0 | J21: =G21 -> 0 | K21: =IF(F21="","",J21-F21+1) | N21: =NETWORKDAYS(F21,J21) -> 0 | O21: =IFERROR(ROUNDDOWN(I21*H21,0),"") | P21: =IFERROR(ROUNDDOWN(I21*K21,0),"") | Q21: =IFERROR(K21-P21,"")
B22: 2.4 | C22: 기구BOM | H22: =IF(F22="","",G22-F22+1) | I22: 0 | J22: =G22 -> 0 | K22: =IF(F22="","",J22-F22+1) | L22: =IF(J22>G22,J22-G22,"") | M22: =NETWORKDAYS(F22,G22) -> 0 | N22: =NETWORKDAYS(F22,J22) -> 0 | O22: =IFERROR(ROUNDDOWN(I22*H22,0),"") | P22: =IFERROR(ROUNDDOWN(I22*K22,0),"") | Q22: =IFERROR(K22-P22,"")
B23: 2.5 | C23: 2D설계(제작도면) | H23: =IF(F23="","",G23-F23+1) | I23: 0 | J23: =G23 -> 0 | K23: =IF(F23="","",J23-F23+1) | L23: =IF(J23>G23,J23-G23,"") | M23: =NETWORKDAYS(F23,G23) -> 0 | N23: =NETWORKDAYS(F23,J23) -> 0 | O23: =IFERROR(ROUNDDOWN(I23*H23,0),"") | P23: =IFERROR(ROUNDDOWN(I23*K23,0),"") | Q23: =IFERROR(K23-P23,"")
B24: 2.6 | C24: 제작BOM | H24: =IF(F24="","",G24-F24+1) | I24: 0 | J24: =G24 -> 0 | K24: =IF(F24="","",J24-F24+1) | L24: =IF(J24>G24,J24-G24,"") | M24: =NETWORKDAYS(F24,G24) -> 0 | N24: =NETWORKDAYS(F24,J24) -> 0 | O24: =IFERROR(ROUNDDOWN(I24*H24,0),"") | P24: =IFERROR(ROUNDDOWN(I24*K24,0),"") | Q24: =IFERROR(K24-P24,"")
B25: 2.7 | C25: 배선제작 | H25: =IF(F25="","",G25-F25+1) | I25: 0 | J25: =G25 -> 0 | K25: =IF(F25="","",J25-F25+1) | L25: =IF(J25>G25,J25-G25,"") | M25: =NETWORKDAYS(F25,G25) -> 0 | N25: =NETWORKDAYS(F25,J25) -> 0 | O25: =IFERROR(ROUNDDOWN(I25*H25,0),"") | P25: =IFERROR(ROUNDDOWN(I25*K25,0),"") | Q25: =IFERROR(K25-P25,"")
B26: 3 | C26: 시제품제작 | E26: 이우원 | F26: =MIN(F27:F32) -> 0 | G26: =MAX(G27:G32) -> 0 | H26: =IF(F26=0,"",G26-F26+1) | I26: =IFERROR(SUMPRODUCT(H27:H32,I27:I32)/SUM(H27:H32),"") | J26: =IF(MAX(J27:J32)="","",MAX(J27:J32)) -> 0 | K26: =J26-F26+1 -> 1 | M26: =NETWORKDAYS(F26,G26) -> 0 | N26: =NETWORKDAYS(F26,J26) -> 0 | O26: =IFERROR(ROUNDDOWN(I26*H26,0),"") | P26: =IFERROR(ROUNDDOWN(I26*K26,0),"") | Q26: =IFERROR(H26-O26,"") | R26: =K26-P26 -> #VALUE!
B27: 3.1 | C27: Part list 자재 발주 | H27: =IF(F27="","",G27-F27+1) | I27: 0 | J27: =G27 -> 0 | K27: =IF(F27="","",J27-F27+1) | L27: =IF(J27>G27,J27-G27,"") | M27: =NETWORKDAYS(F27,G27) -> 0 | N27: =NETWORKDAYS(F27,J27) -> 0 | O27: =IFERROR(ROUNDDOWN(I27*H27,0),"") | P27: =IFERROR(ROUNDDOWN(I27*K27,0),"") | Q27: =IFERROR(K27-P27,"")
B28: 2.2 | C28: 전기 자재 발주 | H28: =IF(F28="","",G28-F28+1) | I28: 0 | J28: =G28 -> 0 | K28: =IF(F28="","",J28-F28+1) | L28: =IF(J28>G28,J28-G28,"") | M28: =NETWORKDAYS(F28,G28) -> 0 | N28: =NETWORKDAYS(F28,J28) -> 0 | O28: =IFERROR(ROUNDDOWN(I28*H28,0),"") | P28: =IFERROR(ROUNDDOWN(I28*K28,0),"") | Q28: =IFERROR(K28-P28,"")
B29: 2.3 | C29: 기구 자재 발주 | H29: =IF(F29="","",G29-F29+1) | I29: 0 | J29: =G29 -> 0 | K29: =IF(F29="","",J29-F29+1) | L29: =IF(J29>G29,J29-G29,"") | M29: =NETWORKDAYS(F29,G29) -> 0 | N29: =NETWORKDAYS(F29,J29) -> 0 | O29: =IFERROR(ROUNDDOWN(I29*H29,0),"") | P29: =IFERROR(ROUNDDOWN(I29*K29,0),"") | Q29: =IFERROR(K29-P29,"")
B30: 2.4 | C30: 배선 자재 발주 | H30: =IF(F30="","",G30-F30+1) | I30: 0 | J30: =G30 -> 0 | K30: =IF(F30="","",J30-F30+1) | L30: =IF(J30>G30,J30-G30,"") | M30: =NETWORKDAYS(F30,G30) -> 0 | N30: =NETWORKDAYS(F30,J30) -> 0 | O30: =IFERROR(ROUNDDOWN(I30*H30,0),"") | P30: =IFERROR(ROUNDDOWN(I30*K30,0),"") | Q30: =IFERROR(K30-P30,"")
B31: 2.5 | C31: 제품 조립 | H31: =IF(F31="","",G31-F31+1) | I31: 0 | J31: =G31 -> 0 | K31: =IF(F31="","",J31-F31+1) | L31: =IF(J31>G31,J31-G31,"") | M31: =NETWORKDAYS(F31,G31) -> 0 | N31: =NETWORKDAYS(F31,J31) -> 0 | O31: =IFERROR(ROUNDDOWN(I31*H31,0),"") | P31: =IFERROR(ROUNDDOWN(I31*K31,0),"") | Q31: =IFERROR(K31-P31,"")
B32: 2.6 | C32: 출하 평가 | H32: =IF(F32="","",G32-F32+1) | I32: 0 | J32: =G32 -> 0 | K32: =IF(F32="","",J32-F32+1) | L32: =IF(J32>G32,J32-G32,"") | M32: =NETWORKDAYS(F32,G32) -> 0 | N32: =NETWORKDAYS(F32,J32) -> 0 | O32: =IFERROR(ROUNDDOWN(I32*H32,0),"") | P32: =IFERROR(ROUNDDOWN(I32*K32,0),"") | Q32: =IFERROR(K32-P32,"")

Sheet 영업 보고 건
E1: 고객 정보 | F1: 납품 일정
B2: 리텍 | C2: 배터리 팩 | D2: 영업 | E2: 1) 전지 사양 : 380V45Ah 배터리 팩 2) 납품 수량 : 6EA 3) 고객 희망 : 17,000천원/1EA 4) 희망 납기 : 3월말 5) 제작 방안 : 설계(HIS)->제작(엘리트) 제작 의뢰 6) 이슈 상황 -. P40 레이저 용접 가능 확인 | F2: 3월말
B3: 충남대 | C3: 배터리 팩 | D3: 제작 | E3: 1) 전지 사양 : 642V50Ah 배터리 팩(시제품) 2) 납품 수량 : 2EA 3) 고객 희망 : 34,000천원/1EA 4) 희망 납기 : 협의 중 5) 제작 방안 : 설계(HIS) 6) 이슈 상황 -. 제작 일정 협의
B4: 충남대 | C4: 배터리 팩 | D4: 제작 | E4: 1) 전지 사양 : 642V50Ah 배터리 팩(양산제품), IP65 2) 납품 수량 : 4EA 3) 고객 희망 : 60,000천원/1EA 4) 희망 납기 : 협의 중 5) 제작 방안 : 설계 6) 이슈 상황 -. 냉각 장치 선정, 배터리 팩 외함 제작
B5: 글로버텍 | C5: 배터리 팩 | D5: 제작 | E5: 1) 전지 사양 : 642V50Ah 배터리 팩(양산제품), IP65 2) 납품 수량 : 4EA 3) 고객 희망 : 60,000천원/1EA 4) 희망 납기 : 협의 중 5) 제작 방안 : 설계 6) 이슈 상황 -. 냉각 장치 선정, 배터리 팩 외함 제작
B6: 자체 양산 | C6: 배터리 팩 | D6: 컨테이너 트럭 보조배터리 팩 | E6: 1) 이슈 상황 -. 양방향 충전기 개발 및 양산 방안 -. 문의 중국 왜 우리 설계 시제품 있으면, 양산 개발 단가 저렴한 이유 대한 설명 | G6: 사업 계획서
B7: 자체 양산 | C7: 배터리 팩 | D7: 현대자동차 | E7: 1) 10kWFC_배터리 팩 성능 평가 위한 용역 개발 2) 중국 현대자동차 내 생산 3) 영업 : 중국 내 지게차 및 모빌리티 업체 판매 계획 4) 개발 한국 진행 생산 중국 5) 파라시어 / 정보 역량
B8: 자체 양산 | C8: 충전기 | E8: 1) 충전기 : 2) 충전기 인증 : HIS

Sheet 이슈리스트
B2: WBS ID | F2: 프로젝트명 | G2: 대분류 | H2: 중분류 | I2: 소분류 | J2: 대응순위 | K2: 고객사 | L2: 이슈제목 /이슈내용/해결방안/기타 | M2: 최초 발생일 | N2: 완료일 | O2: 상태 | P2: 추적 번호 | Q2: 제품 버전 | R2: 담당자 | S2: 검토/승인자 지시사항 | T2: 추진 일정 및 조치 현황 | U2: 비고
B3: 2 | C3: 2 | D3: 1 | E3: 4 | F3: 10kWFC_NCM배터리팩 | G3: 제품설계 | H3: 회로설계 | I3: 제작변경 | K3: HMC | L3: 1)온도센서, 전압센싱 케이블 제작 확인 2) 제작일정 상 HIS내부 제작 또는 외주 제작 여부 확인 3) 온도센서 부착후 모듈 적층 가능함. 케이블 길이 3D설계완(검토의견 회신 대기중) | M3: 46037 | O3: 완료 | Q3: 시작품 | R3: 문병길 | T3: 1) 내부에서 제작 진행을 바랍니다 | U3: 2024 제품사업화\25-05 수소지게차용 배터리모듈개발 (현대자동차)\08. 전기도면 및 BOM
B4: 2 | C4: 2 | D4: 1 | E4: 4 | F4: 10kWFC_NCM배터리팩 | G4: 제품설계 | H4: 회로설계 | I4: 제작변경 | K4: HMC | L4: 1) Slave BMS 온도센서 커넥터 변경 건 2) 스트레이트에서 앵글타입으로 변경 가능 여부 3) Slave BMS 변경없이 모듈 옆면 플레이트 제거후 부착 Slave BMS 커넥터 스트레이트로 변경 | M4: 46037 | Q4: 시작품 | R4: 문병길 | T4: 1) 화상보고해주세요
B5: 1 | C5: 2 | D5: 1 | E5: 1 | F5: 긴트 SS기 배터리 팩 | K5: GINT | L5: 팩 외함 높이 225mm로 유지 요청받음. 팩BMS는 상부에 위치 가능한 방법 검토 필요 | M5: 46037 | N5: 46042 | O5: 완료 | Q5: 양산제품 | R5: 문병길 | S5: 1) 팩 외함 높이 225mm 제작 2) PACK BMS 내 CPU 모듈 직접 조립함 | T5: 2D,3D,BOM 변경 완료
B6: 0 | C6: 5 | D6: 2 | E6: 4 | F6: 제품 장비 관리 | K6: 내부 | L6: 1) 레이져 용접설비 내 산업컴퓨터 부팅 불가 2) 울산 컴퓨터 복구업체 컨택및 파라시스 협력사 레이져 용접 의뢰 | M6: 46041 | R6: 박성호 | S6: 1) 레이저용접 개발자 문의 통해 해결 2) 컴퓨터에서 문의 통해 불량 제품 교환 요청 | T6: 1) 복구업체에서 컴퓨터 부품 수리 후 SW업체 별도 수배 진행 2) 김상걸 대표 방문하여 제품 정상 동작
